Workbook

Sheet var
A1: no | B1: user_id | C1: name | D1: dep | I1: no | J1: no_perjanjian | K1: nopol | L1: nama_nasabah | M1: nopol | N1: coll | O1: pic | P1: kategori | Q1: jto | R1: no_rangka | S1: no_mesin | T1: merk | U1: type | V1: warna | W1: status | X1: actual_penyelesaian | Y1: angsuran_ke | Z1: tenor
A2: 1 | B2: 03ad1f6b-7a85-463b-ab53-e8f3deee2ad5 | C2: Ray Steven Hutabarat | D2: COLL | E2: 03ad1f6b-7a85-463b-ab53-e8f3deee2ad5 | I2: 6056 | J2: DATA LUAR 9071 | K2: BP2511AJ | L2: DEDY SETIAWAN | M2: BP BP25 11A | S2: JM11E2170408 | T2: BEAT CBS ISS | U2: BEAT CBS ISS | V2: MERAH HITAM | W2: JP GADAI | X2: TIDAK DIKETAHUI
A3: 2 | B3: 0787ea2f-240f-4392-bead-e10cba282613 | C3: Rizkiii | D3: COLL | E3: 0787ea2f-240f-4392-bead-e10cba282613 | I3: 6057 | J3: DATA LUAR 9072 | K3: BP3381RJ | L3: RAFAEL GIAWA | M3: BP BP33 81R | S3: JM02E1691516 | T3: SCOOPY PGM FI | U3: SCOOPY PGM FI | V3: MERAH | W3: JP GADAI | X3: TIDAK DIKETAHUI
A4: 3 | B4: 1221336c-e009-42e3-be62-cbcd8f4b6108 | C4: Josri sijabat | D4: COLL | E4: 1221336c-e009-42e3-be62-cbcd8f4b6108 | I4: 6058 | J4: DATA LUAR 9073 | K4: BP2413PU | L4: GEOVANI MARBUN | M4: BP BP24 13P | S4: JM81E2606073 | T4: BEAT CBS | U4: BEAT CBS | V4: MERAH-HITAM | W4: JP GADAI | X4: TIDAK DIKETAHUI
A5: 4 | B5: 1544d06d-d3ae-4f27-a81b-96b8341d1255 | C5: Muhamad yusfik | D5: ALL | E5: 1544d06d-d3ae-4f27-a81b-96b8341d1255 | I5: 6059 | J5: DATA LUAR 9074 | K5: BP3092HF | L5: RIAN HIDAYATULLAH | M5: BP BP30 92H | S5: JM21E1853635 | T5: BEAT CBS | U5: BEAT CBS | V5: HITAM | W5: JP GADAI | X5: TIDAK DIKETAHUI
A6: 5 | B6: 1770dac3-81ca-4fab-8a6a-e60c63470def | C6: M Arkha Raditya Wuekero | D6: COLL | E6: 1770dac3-81ca-4fab-8a6a-e60c63470def | I6: 6060 | J6: DATA LUAR 9075 | K6: BP2885IA | L6: FARDUAN FAUZI | M6: BP BP28 85I | S6: JFZ1E1945198 | T6: BEAT CBS | U6: BEAT CBS | V6: HITAM | W6: JP GADAI | X6: TIDAK DIKETAHUI
A7: 6 | B7: 1cdd9278-f5fc-47ec-adf2-de5f869fef9b | C7: Refan | D7: COLL | E7: 1cdd9278-f5fc-47ec-adf2-de5f869fef9b | I7: 6061 | J7: DATA LUAR 9076 | K7: BP3583UI | L7: AMSELMUS NIARANG | M7: BP BP35 83U | S7: JM81E1764845 | T7: BEAT CBS | U7: BEAT CBS | V7: HITAM | W7: JP GADAI | X7: TIDAK DIKETAHUI
A8: 7 | B8: 1e3f8b18-4709-402b-864e-d3700b5c6a58 | C8: Alwan simbolon | D8: COLL | E8: 1e3f8b18-4709-402b-864e-d3700b5c6a58 | I8: 6062 | J8: DATA LUAR 9077 | K8: BP3214UM | L8: MILLENY AFRILIA PRAMITA | M8: BP BP32 14U | S8: JM81E1251726 | T8: BEAT CBS | U8: BEAT CBS | V8: PUTIH | W8: JP GADAI | X8: TIDAK DIKETAHUI
A9: 8 | B9: 306820e2-08cc-4078-ae54-edf70712dc0f | C9: Wilfrin samosir | D9: COLL | E9: 306820e2-08cc-4078-ae54-edf70712dc0f
A10: 9 | B10: 1e9acb24-9056-40a0-9e92-a3976369bb8b | C10: Bintang Cristian H Siahaan | D10: COLL | E10: 1e9acb24-9056-40a0-9e92-a3976369bb8b | I10: 6063 | J10: DATA LUAR 9078 | K10: BP2918QQ | L10: MAULANA RABIANSYAH | M10: BP BP29 18Q | S10: JFZ2E1030959 | T10: BEAT STREET | U10: BEAT STREET | V10: HITAM | W10: JP GADAI | X10: TIDAK DIKETAHUI
A11: 10 | B11: 240e927b-449f-4469-8c98-e687f0b41cf8 | C11: Rintoeriksonsiburian | D11: COLL | E11: 240e927b-449f-4469-8c98-e687f0b41cf8 | I11: 6064 | J11: DATA LUAR 9079 | K11: BP6433GI | L11: YESRIZON | M11: BP BP64 33G | S11: G427ID386412 | T11: SATRIA FU | U11: SATRIA FU | V11: MERAH HITAM | W11: JP GADAI | X11: TIDAK DIKETAHUI
A12: 11 | B12: 26682316-51f3-44c6-a724-9e9af4c97827 | C12: RIZKI FERDIAN | D12: COLL | E12: 26682316-51f3-44c6-a724-9e9af4c97827 | I12: 6065 | J12: DATA LUAR 9080 | K12: BP2901AH | L12: ROMI DELHAN | M12: BP BP29 01A | S12: JFZ1E3081946 | T12: BEAT CW PGM FI | U12: BEAT CW PGM FI | V12: PUTIH | W12: JP GADAI | X12: TIDAK DIKETAHUI
A13: 12 | B13: 2d5835da-ef4a-416f-a799-2636cdfa60ca | C13: Martin Tri Putra s | D13: COLL | E13: 2d5835da-ef4a-416f-a799-2636cdfa60ca | I13: 6066 | J13: DATA LUAR 9081 | K13: BP3117OD | L13: RYAN TRISDYA SIMANJUNTAK | M13: BP BP31 17O | S13: JM81E1759592 | T13: BEAT CBS | U13: BEAT CBS | V13: PUTIH HITAM | W13: JP GADAI | X13: TIDAK DIKETAHUI
A14: 13 | B14: 2d9d422f-1d0e-4451-8950-dc9e388e3850 | C14: Efendi Lim | D14: COLL | E14: 2d9d422f-1d0e-4451-8950-dc9e388e3850 | I14: 6067 | J14: DATA LUAR 9082 | K14: BP3438RF | L14: MUHAMMAD IQBAL S | M14: BP BP34 38R | S14: JM01E1476653 | T14: SCOOPY | U14: SCOOPY | V14: BIRU-KREM | W14: JP GADAI | X14: TIDAK DIKETAHUI
A15: 14 | B15: 300826c6-ffb7-47ae-b0e0-86185483ddb9 | C15: Efendi Limbong | D15: COLL | E15: 300826c6-ffb7-47ae-b0e0-86185483ddb9 | I15: 6068 | J15: DATA LUAR 9083 | K15: BP3226RO | L15: ZULMARWAN | M15: BP BP32 26R | S15: JM91E2182596 | T15: BEAT CBS ISS | U15: BEAT CBS ISS | V15: SILVER | W15: JP GADAI | X15: TIDAK DIKETAHUI
A16: 15 | B16: 366fd226-4dfb-422c-825d-42fff8dda2c7 | C16: Aldila Fahri | D16: ALL | E16: 366fd226-4dfb-422c-825d-42fff8dda2c7 | I16: 6069 | J16: DATA LUAR 9084 | K16: BP3642HU | L16: ABDUL GANI | M16: BP BP36 42H | S16: JFZ1E2843909 | T16: BEAT CW PGM FI | U16: BEAT CW PGM FI | V16: HITAM | W16: JP GADAI | X16: TIDAK DIKETAHUI
A17: 16 | B17: 3677fb97-4982-45ef-bdd0-66ca3ee452fd | C17: riduwankhafidi | D17: COLL | E17: 3677fb97-4982-45ef-bdd0-66ca3ee452fd | I17: 6070 | J17: DATA LUAR 9085 | K17: BP3459UD | L17: RINO KARNO SINAGA | M17: BP BP34 59U | S17: JFZ1E3586785 | T17: BEAT CW PGM FI | U17: BEAT CW PGM FI | V17: HITAM | W17: JP GADAI | X17: TIDAK DIKETAHUI
A18: 17 | B18: 37e0a962-8be0-4256-a63a-51a09fd71ba6 | C18: Satria | D18: COLL | E18: 37e0a962-8be0-4256-a63a-51a09fd71ba6 | I18: 6071 | J18: DATA LUAR 9086 | K18: BP3374HM | L18: MUKMININ | M18: BP BP33 74H | S18: JFZ1E2660808 | T18: BEAT CW FGM FI | U18: BEAT CW FGM FI | V18: HITAM | W18: JP GADAI | X18: TIDAK DIKETAHUI
A19: 18 | B19: 3841b94e-9a4f-4b53-a473-36560f4d9a4f | C19: Miduk situmeangmiduk | D19: COLL | E19: 3841b94e-9a4f-4b53-a473-36560f4d9a4f | I19: 6072 | J19: DATA LUAR 9087 | K19: BP6252GF | L19: IKRAR MAULANA | M19: BP BP62 52G | S19: G427ID307445 | T19: SATRIA FU | U19: SATRIA FU | V19: BIRU | W19: JP GADAI | X19: TIDAK DIKETAHUI
A20: 19 | B20: 38fa4eda-b9a3-44ff-9898-d074c99008b7 | C20: Zaen | D20: COLL | E20: 38fa4eda-b9a3-44ff-9898-d074c99008b7 | I20: 6073 | J20: DATA LUAR 9088 | K20: BP6407GI | L20: RISKI ANANDA SIMAMORA | M20: BP BP64 07G | S20: G427ID377145 | T20: SATRIA FU | U20: SATRIA FU | V20: HITAM | W20: JP GADAI | X20: TIDAK DIKETAHUI
A21: 20 | B21: 3be3f0c1-373f-4a45-946b-0ab494863da5 | C21: Afsyah Tanjung | D21: COLL | E21: 3be3f0c1-373f-4a45-946b-0ab494863da5 | I21: 6074 | J21: DATA LUAR 9089 | K21: BP3359OF | L21: MINAN SUNANDAR | M21: BP BP33 59O | S21: JFP1E1682281 | T21: BEAT CW | U21: BEAT CW | V21: HITAM | W21: JP GADAI | X21: TIDAK DIKETAHUI
... A30: 29 | B30: 584bc6b7-bc3a-4d84-a66b-857e86f329da | C30: Syafiq | D30: COLL | E30: 584bc6b7-bc3a-4d84-a66b-857e86f329da | I30: 6083 | J30: DATA LUAR 9098 | K30: BP3593QA | L30: MUHAMMAD RIDWAN | M30: BP BP35 93Q | S30: JFP1E2214382 | T30: BEAT CW | U30: BEAT CW | V30: PUTIH-MERAH | W30: JP GADAI | X30: TIDAK DIKETAHUI
A31: 30 | B31: 5a9c7fd1-cce7-4fe3-8276-b4f3c2c3057f | C31: Brian Natanael Nainggolan | D31: ALL | E31: 5a9c7fd1-cce7-4fe3-8276-b4f3c2c3057f | I31: 6084 | J31: DATA LUAR 9099 | K31: BP3468QA | L31: DELVIAN FERBIANTO | M31: BP BP34 68Q | R31: MH1KC8213GK010339 | S31: KC82E1010135 | T31: H. CB150 R | U31: H. CB150 R H5C02R20M1 M/T tahun:2016 | V31: MERAH HITAM | W31: MEGA MAS GADAI | X31: TIDAK DIKETAHUI
A32: 31 | B32: 5d155998-3b32-426c-9f80-9898af00922a | C32: REFAN ANUGRAH MANALU | D32: COLL | E32: 5d155998-3b32-426c-9f80-9898af00922a | I32: 6085 | J32: DATA LUAR 9100 | K32: BP2563AF | L32: SRI WAYUNI | M32: BP BP25 63A | R32: MH1JFZ134KK125679 | S32: JFZ1E3127705 | T32: H.BEAT | U32: D1B02N26L2 A/T/2019 | V32: HITAM | W32: MEGA MAS GADAI | X32: TIDAK DIKETAHUI
A33: 32 | B33: 6159b013-1d5d-41e6-b081-c5781a4ea31b | C33: Talenta sihombing | D33: COLL | E33: 6159b013-1d5d-41e6-b081-c5781a4ea31b | I33: 6086 | J33: DATA LUAR 9101 | K33: BP2668Q | L33: FERLI OKTAWARDINATA | M33: BP BP26 68Q | R33: MH1JM0417PK235628 | S33: JM04E1235571 | T33: H. SCOOPY | U33: H. SCOOPY F1C02N46L0 A/T tahun:2023 | V33: MERAH | W33: MEGA MAS GADAI | X33: TIDAK DIKETAHUI
A34: 33 | B34: 6334c9e2-f39a-47fc-883e-dc49b291c247 | C34: Willy Tambunan | D34: COLL | E34: 6334c9e2-f39a-47fc-883e-dc49b291c247 | I34: 6087 | J34: DATA LUAR 9102 | K34: BP2796CR | L34: VITA RAMADHONA | M34: BP BP27 96C | R34: MH1KF0112NK168324 | S34: KF01E1168444 | T34: H.VARIO | U34: H.VARIO X1H02N32L1 A/T tahun:2022 | V34: HITAM | W34: MEGA MAS GADAI | X34: TIDAK DIKETAHUI
A35: 34 | B35: 65a61a5a-d553-4abf-aa0b-8bf217516db0 | C35: Khatijah Fitriyana | D35: COLL | E35: 65a61a5a-d553-4abf-aa0b-8bf217516db0 | I35: 6088 | J35: DATA LUAR 9103 | K35: BP2841RI | L35: EKA PUSPADEWI | M35: BP BP28 41R | R35: MH1KFA110NK010506 | S35: KFA1E1010375 | T35: H.VARIO | U35: L1K02Q33L1 A/T 2022 | V35: HITAM | W35: MEGA MAS GADAI | X35: TIDAK DIKETAHUI
A36: 35 | B36: 65a89e1c-a896-41d3-80db-f77bc1515e6d | C36: GLADYS STEPHANIE ANDI LOLO | D36: COLL | E36: 65a89e1c-a896-41d3-80db-f77bc1515e6d | I36: 6089 | J36: DATA LUAR 9104 | K36: BP3722MF | L36: SUPARJON | M36: BP BP37 22M | R36: MH1KC411XEK216488 | S36: KC41E1214360 | T36: H.CBR | U36: CB15A1RRF/2014 | V36: HITAM | W36: MEGA MAS GADAI | X36: TIDAK DIKETAHUI
A37: 36 | B37: 65c1341a-686d-45fb-810f-7b8814abe13f | C37: Martin Tri Putra Situmeang | D37: COLL | E37: 65c1341a-686d-45fb-810f-7b8814abe13f | I37: 6090 | J37: DATA LUAR 9105 | K37: BP3808RQ | L37: ENJELINA KARO KARO | M37: BP BP38 08R | R37: MH1JM0211NK780711 | S37: JM02E1780738 | T37: H.SCOOPY | U37: H.SCOOPY F1C02N46L0 A/T tahun:2022 | V37: COKLAT | W37: MEGA MAS GADAI | X37: TIDAK DIKETAHUI
A38: 37 | B38: 66338f6f-6199-47e8-8fc9-c871a18b6d2c | C38: Daulat sitorus | D38: COLL | E38: 66338f6f-6199-47e8-8fc9-c871a18b6d2c | I38: 6091 | J38: DATA LUAR 9106 | K38: BP4436GR | L38: RENDI WIJAYA | M38: BP BP44 36G | R38: MH31PA002DK338699 | S38: 1PA338798 | T38: Y.VIXION | U38: H.VIXION 1PA tahun:2013 | V38: PUTIH | W38: MEGA MAS GADAI | X38: TIDAK DIKETAHUI
A39: 38 | B39: 688868a7-408e-44ae-b238-348dfc1995b0 | C39: Juliendra | D39: COLL | E39: 688868a7-408e-44ae-b238-348dfc1995b0 | I39: 6092 | J39: DATA LUAR 9107 | K39: BP5497IC | L39: JONI PRANATA MANULANG | M39: BP BP54 97I | R39: MH32PK001EK010989 | S39: 2PK010920 | T39: Y.R15 | U39: 2 PK tahun:2014 | V39: PUTIH BIRU | W39: MEGA MAS GADAI | X39: TIDAK DIKETAHUI
A40: 39 | B40: 6b2e8be3-4c18-47cd-bfc4-5a119bd3b15d | C40: Galih sangga persada | D40: ALL | E40: 6b2e8be3-4c18-47cd-bfc4-5a119bd3b15d | I40: 6093 | J40: DATA LUAR 9108 | K40: BP5729MF | L40: MARDIANA SITORUS | M40: BP BP57 29M | R40: MH354P00CDJ975926 | S40: 54P975991 | T40: Y.MIO | U40: Y.MIO J 54P (CAST WHEEL) A/T tahun:2013 | V40: BIRU | W40: MEGA MAS GADAI | X40: TIDAK DIKETAHUI
A41: 40 | B41: 6b3dc071-be8e-4fa6-84b3-ef2c87247cf2 | C41: Opendi banjarnahor | D41: COLL | E41: 6b3dc071-be8e-4fa6-84b3-ef2c87247cf2 | I41: 6094 | J41: DATA LUAR 9109 | K41: BP2005FK | L41: DEBY AULIA SONDAKH | M41: BP BP20 05F | R41: MH1JM9114MK733600 | S41: JM91E1715864 | T41: H. BEAT DELUXE | U41: H. BEAT DELUXE H1B02N42L0 A/T tahun:2021 | V41: COKLAT | W41: MEGA MAS GADAI | X41: TIDAK DIKETAHUI
A42: 41 | B42: 6d21de4b-42fc-49f2-86f3-40a2a9759695 | C42: Roby radiansyah | D42: COLL | E42: 6d21de4b-42fc-49f2-86f3-40a2a9759695 | I42: 6095 | J42: DATA LUAR 9110 | K42: BP2081AD | L42: CANDRA SARI DEWI | M42: BP BP20 81A | R42: MH1JM3120KK947941 | S42: JM31E2943289 | T42: H.SCOOPY | U42: F1C02N28L0 A/T tahun:2019 | V42: HITAM | W42: MEGA MAS GADAI | X42: TIDAK DIKETAHUI
... A84: 83 | B84: 4ba588ce-5b23-48f8-84fd-4b03202c6b6a | C84: Nisa | D84: COLL | E84: 4ba588ce-5b23-48f8-84fd-4b03202c6b6a | I84: 6137 | J84: DATA LUAR 9152 | K84: BP3459HI | L84: ALFIYAH | M84: BP BP34 59H | R84: MH1JM2112JK939257 | S84: JM21E1919461 | T84: H.BEAT | U84: D1B02N12L2 A/T/2018 | V84: HITAM | W84: MEGA MAS GADAI | X84: TIDAK DIKETAHUI
A85: 84 | B85: c3350f0e-6142-40d5-b484-65615d63ec42 | C85: Susi Susanti | D85: ALL | E85: =B85 -> c3350f0e-6142-40d5-b484-65615d63ec42 | I85: 6138 | J85: DATA LUAR 9153 | K85: BP3467JH | L85: ZAINAL ARIFIN | M85: BP BP34 67J | R85: MH1JFD222DK241510 | S85: JFD2E2238299 | T85: H BEAT | U85: H.BEAT NC11BF1D A/T tahun:2013 | V85: HIJAU-PUTIH | W85: MEGA MAS GADAI | X85: TIDAK DIKETAHUI
A86: 85 | B86: 7a853851-d132-44d5-857c-82270c574879 | C86: M. UMAR FARUK | D86: ALL | E86: =B86 -> 7a853851-d132-44d5-857c-82270c574879 | I86: 6139 | J86: DATA LUAR 9154 | K86: BP3477RG | L86: ANDES HASONANGAN | M86: BP BP34 77R | R86: MH1JM8113NK873584 | S86: JM81E1877632 | T86: H BEAT | U86: D1B02N26L2 A/T tahun:2019 | V86: HITAM | W86: MEGA MAS GADAI | X86: TIDAK DIKETAHUI
A87: 86 | B87: 9cd0556f-4824-4d89-9026-53770f8d3dda | C87: Daniel andrianto | D87: ALL | E87: =B87 -> 9cd0556f-4824-4d89-9026-53770f8d3dda | I87: 6140 | J87: DATA LUAR 9155 | K87: BP3499J | L87: ROIDIN | M87: BP BP34 99J | R87: MH1JM8116MK694504 | S87: JM81E1696592 | T87: H. BEAT | U87: H. BEAT H1B02N41L0 A/T tahun:2021 | V87: BIRU - HITAM | W87: MEGA MAS GADAI | X87: TIDAK DIKETAHUI
A88: 87 | B88: 6b385b18-dcd8-469a-8210-e2ae95246bd3 | C88: Samsir | D88: ALL | E88: =B88 -> 6b385b18-dcd8-469a-8210-e2ae95246bd3 | I88: 6141 | J88: DATA LUAR 9156 | K88: BP3505RJ | L88: NURUL AINUN | M88: BP BP35 05R | R88: MH1JM9126NK154991 | S88: JM91E2153654 | T88: H. BEAT DELUXE | U88: H. BEAT DELUXE H1B02N42L0 A/T tahun:2022 | V88: COKLAT | W88: MEGA MAS GADAI | X88: TIDAK DIKETAHUI
A89: 88 | B89: 104aa0bc-4e85-4677-9b2c-8428b6a82e94 | C89: Afrianto Sianipar | D89: ALL | E89: =B89 -> 104aa0bc-4e85-4677-9b2c-8428b6a82e94 | I89: 6142 | J89: DATA LUAR 9157 | K89: BP3591QU | L89: DELI TATI SIMAMORA | M89: BP BP35 91Q | R89: MH1JM8218LK076517 | S89: JM82E1076496 | T89: H. BEAT STREET | U89: H. BEAT STREET H1B02N41L0 A/T tahun:2020 | V89: SILVER - HITAM | W89: MEGA MAS GADAI | X89: TIDAK DIKETAHUI
...

Sheet sortir
A1: trim_name | B1: key | C1: velue | E1: TOTAL
A2: RIZKI A | B2: fb0bf344-260b-448c-b9d1-41fee67eb951 | C2: =IFERROR(VLOOKUP(B2,input!$A$2:$B$1048576,2,0),"") | E2: =SUM(C2:C61) -> 5914
A3: ALJABAR | B3: e8e7929e-42ea-42fd-ba15-6abadcfc1320 | C3: =IFERROR(VLOOKUP(B3,input!$A$2:$B$1048576,2,0),"")
A4: BOSPA | B4: 86c5db36-c6d1-4806-9a2e-31a2483c0bb3 | C4: =IFERROR(VLOOKUP(B4,input!$A$2:$B$1048576,2,0),"") -> 26
A5: ROBEN | B5: e3a70ada-a915-4680-aaa7-28e4b7d6722b | C5: =IFERROR(VLOOKUP(B5,input!$A$2:$B$1048576,2,0),"") -> 18
A6: RINTO | B6: 240e927b-449f-4469-8c98-e687f0b41cf8 | C6: =IFERROR(VLOOKUP(B6,input!$A$2:$B$1048576,2,0),"") -> 35
A7: JOSRI | B7: 1221336c-e009-42e3-be62-cbcd8f4b6108 | C7: =IFERROR(VLOOKUP(B7,input!$A$2:$B$1048576,2,0),"") -> 1
A8: OLOAN | B8: b5022170-5138-4d36-a599-749fef2d3ebb | C8: =IFERROR(VLOOKUP(B8,input!$A$2:$B$1048576,2,0),"")
A9: MIDUK | B9: 3841b94e-9a4f-4b53-a473-36560f4d9a4f | C9: =IFERROR(VLOOKUP(B9,input!$A$2:$B$1048576,2,0),"") -> 3
A10: RIMPUN | B10: eea94692-e3ef-470d-a986-47d8940e37c5 | C10: =IFERROR(VLOOKUP(B10,input!$A$2:$B$1048576,2,0),"") -> 1
A11: JUBRAIDER | B11: 83ca24fc-042d-4a7a-aea3-35465e9db033 | C11: =IFERROR(VLOOKUP(B11,input!$A$2:$B$1048576,2,0),"") -> 41
A12: WILFRIN | B12: 306820e2-08cc-4078-ae54-edf70712dc0f | C12: =IFERROR(VLOOKUP(B12,input!$A$2:$B$1048576,2,0),"")
A13: REY | B13: 03ad1f6b-7a85-463b-ab53-e8f3deee2ad5 | C13: =IFERROR(VLOOKUP(B13,input!$A$2:$B$1048576,2,0),"") -> 5
C14: =IFERROR(VLOOKUP(B14,input!$A$2:$B$1048576,2,0),"")
A15: DOKA | B15: 97b899c7-a738-4c0c-a57d-47d1be720bd2 | C15: =IFERROR(VLOOKUP(B15,input!$A$2:$B$1048576,2,0),"") -> 76
A16: EFENDI | B16: 2d9d422f-1d0e-4451-8950-dc9e388e3850 | C16: =IFERROR(VLOOKUP(B16,input!$A$2:$B$1048576,2,0),"") -> 17
A17: MARTIN | B17: 65c1341a-686d-45fb-810f-7b8814abe13f | C17: =IFERROR(VLOOKUP(B17,input!$A$2:$B$1048576,2,0),"")
A18: TALENTA S | B18: 6159b013-1d5d-41e6-b081-c5781a4ea31b | C18: =IFERROR(VLOOKUP(B18,input!$A$2:$B$1048576,2,0),"")
A19: SATRIA | B19: 37e0a962-8be0-4256-a63a-51a09fd71ba6 | C19: =IFERROR(VLOOKUP(B19,input!$A$2:$B$1048576,2,0),"")
A20: PAUL | B20: 908a2117-9e59-4ec5-981c-f44c8e53d59f | C20: =IFERROR(VLOOKUP(B20,input!$A$2:$B$1048576,2,0),"") -> 3
C21: =IFERROR(VLOOKUP(B21,input!$A$2:$B$1048576,2,0),"")
A22: RIZKI | B22: 0787ea2f-240f-4392-bead-e10cba282613 | C22: =IFERROR(VLOOKUP(B22,input!$A$2:$B$1048576,2,0),"")
A23: ZAEN | B23: 38fa4eda-b9a3-44ff-9898-d074c99008b7 | C23: =IFERROR(VLOOKUP(B23,input!$A$2:$B$1048576,2,0),"")
A24: PARNI | B24: 7be4daec-f2f2-4566-a79d-37f472fd73b1 | C24: =IFERROR(VLOOKUP(B24,input!$A$2:$B$1048576,2,0),"")
A25: RIDWAN | B25: 3677fb97-4982-45ef-bdd0-66ca3ee452fd | C25: =IFERROR(VLOOKUP(B25,input!$A$2:$B$1048576,2,0),"")
A26: NISA | B26: 4ba588ce-5b23-48f8-84fd-4b03202c6b6a | C26: =IFERROR(VLOOKUP(B26,input!$A$2:$B$1048576,2,0),"")
A27: KHATIJAH FITRI | B27: 65a61a5a-d553-4abf-aa0b-8bf217516db0 | C27: =IFERROR(VLOOKUP(B27,input!$A$2:$B$1048576,2,0),"")
C28: =IFERROR(VLOOKUP(B28,input!$A$2:$B$1048576,2,0),"")
A29: BP TIOPAN | B29: fced54d3-7c26-48e8-91fe-7d7236e7f959 | C29: =IFERROR(VLOOKUP(B29,input!$A$2:$B$1048576,2,0),"") -> 3
A30: AFSYAH | B30: 3be3f0c1-373f-4a45-946b-0ab494863da5 | C30: =IFERROR(VLOOKUP(B30,input!$A$2:$B$1048576,2,0),"")
A31: MUTIA | B31: 776aec09-4bd9-4191-a74b-53a47f4274b5 | C31: =IFERROR(VLOOKUP(B31,input!$A$2:$B$1048576,2,0),"")
A32: OPENDI | B32: 6b3dc071-be8e-4fa6-84b3-ef2c87247cf2 | C32: =IFERROR(VLOOKUP(B32,input!$A$2:$B$1048576,2,0),"") -> 3
A33: HARDIMAN | B33: a4f24bfd-45be-407a-a9ce-5da8e226108b | C33: =IFERROR(VLOOKUP(B33,input!$A$2:$B$1048576,2,0),"")
C34: =IFERROR(VLOOKUP(B34,input!$A$2:$B$1048576,2,0),"")
A35: BP HENDRA IMS | B35: 7940f202-c0c3-4d50-8007-8a6b016ada87 | C35: =IFERROR(VLOOKUP(B35,input!$A$2:$B$1048576,2,0),"")
A36: BP CRIS IMS | B36: 9a84d740-169d-4318-8369-6974d75bb07e | C36: =IFERROR(VLOOKUP(B36,input!$A$2:$B$1048576,2,0),"")
A37: AMRIN IMS | C37: =IFERROR(VLOOKUP(B37,input!$A$2:$B$1048576,2,0),"")
A38: BP RENDY IMS | B38: ac63d112-8c59-4edb-b75b-75ebcb97a513 | C38: =IFERROR(VLOOKUP(B38,input!$A$2:$B$1048576,2,0),"") -> 6
C39: =IFERROR(VLOOKUP(B39,input!$A$2:$B$1048576,2,0),"")
A40: DAULAT | B40: 66338f6f-6199-47e8-8fc9-c871a18b6d2c | C40: =IFERROR(VLOOKUP(B40,input!$A$2:$B$1048576,2,0),"") -> 164
...

Sheet input
A1: usrid | B1: count | C1: team | F1: check | G1: check_num | J1: CHECK
A2: 03ad1f6b-7a85-463b-ab53-e8f3deee2ad5 | B2: 5 | C2: =IFERROR(VLOOKUP(A2,var!$B$2:$D$801,3,0),"") -> COLL | F2: =IFERROR(VLOOKUP(A2,sortir!$B$2:$C$60,2,0),"") -> 5 | G2: =IFERROR(VLOOKUP(A2,var!B:C,2,0),"") -> Ray Steven Hutabarat | J2: =SUM(B2:B1048576) -> 5925 | K2: ALL + COLL
A3: 1221336c-e009-42e3-be62-cbcd8f4b6108 | B3: 1 | C3: =IFERROR(VLOOKUP(A3,var!$B$2:$D$801,3,0),"") -> COLL | F3: =IFERROR(VLOOKUP(A3,sortir!$B$2:$C$60,2,0),"") -> 1 | G3: =IFERROR(VLOOKUP(A3,var!B:C,2,0),"") -> Josri sijabat | J3: =SUM(F2:F70) -> 5914 | K3: YANG MASUK KE SORTIR
A4: 1770dac3-81ca-4fab-8a6a-e60c63470def | B4: 428 | C4: =IFERROR(VLOOKUP(A4,var!$B$2:$D$801,3,0),"") -> COLL | F4: =IFERROR(VLOOKUP(A4,sortir!$B$2:$C$60,2,0),"") -> 428 | G4: =IFERROR(VLOOKUP(A4,var!B:C,2,0),"") -> M Arkha Raditya Wuekero | J4: =J2-J3 -> 11 | K4: SELISIH
A5: 240e927b-449f-4469-8c98-e687f0b41cf8 | B5: 35 | C5: =IFERROR(VLOOKUP(A5,var!$B$2:$D$801,3,0),"") -> COLL | F5: =IFERROR(VLOOKUP(A5,sortir!$B$2:$C$60,2,0),"") -> 35 | G5: =IFERROR(VLOOKUP(A5,var!B:C,2,0),"") -> Rintoeriksonsiburian | J5: =SUMIF(C:C,"ALL",B:B) -> 11 | K5: CHEK SELISIH
A6: 2d9d422f-1d0e-4451-8950-dc9e388e3850 | B6: 17 | C6: =IFERROR(VLOOKUP(A6,var!$B$2:$D$801,3,0),"") -> COLL | F6: =IFERROR(VLOOKUP(A6,sortir!$B$2:$C$60,2,0),"") -> 17 | G6: =IFERROR(VLOOKUP(A6,var!B:C,2,0),"") -> Efendi Lim | J6: =SUMIF($C$2:$C$70,$C$4,$B$2:$B$1048576) -> 5914 | K6: JUMLAH ALL
A7: 3841b94e-9a4f-4b53-a473-36560f4d9a4f | B7: 3 | C7: =IFERROR(VLOOKUP(A7,var!$B$2:$D$801,3,0),"") -> COLL | F7: =IFERROR(VLOOKUP(A7,sortir!$B$2:$C$60,2,0),"") -> 3 | G7: =IFERROR(VLOOKUP(A7,var!B:C,2,0),"") -> Miduk situmeangmiduk | J7: =SUMIF($C$2:$C$70,$C$5,$B$2:$B$1048576) -> 5914 | K7: JUMLAH COLL
A8: 51f658db-9885-4d52-99bd-8e1bf0356977 | B8: 497 | C8: =IFERROR(VLOOKUP(A8,var!$B$2:$D$801,3,0),"") -> COLL | F8: =IFERROR(VLOOKUP(A8,sortir!$B$2:$C$60,2,0),"") -> 497 | G8: =IFERROR(VLOOKUP(A8,var!B:C,2,0),"") -> Muhammad Halim Putra
A9: 551fa799-4956-44f4-9122-ea915d0399f1 | B9: 515 | C9: =IFERROR(VLOOKUP(A9,var!$B$2:$D$801,3,0),"") -> COLL | F9: =IFERROR(VLOOKUP(A9,sortir!$B$2:$C$60,2,0),"") -> 515 | G9: =IFERROR(VLOOKUP(A9,var!B:C,2,0),"") -> Miko Nadchipa Sonara
A10: 5d155998-3b32-426c-9f80-9898af00922a | B10: 2 | C10: =IFERROR(VLOOKUP(A10,var!$B$2:$D$801,3,0),"") -> COLL | F10: =IFERROR(VLOOKUP(A10,sortir!$B$2:$C$60,2,0),"") -> 2 | G10: =IFERROR(VLOOKUP(A10,var!B:C,2,0),"") -> REFAN ANUGRAH MANALU
A11: 66338f6f-6199-47e8-8fc9-c871a18b6d2c | B11: 164 | C11: =IFERROR(VLOOKUP(A11,var!$B$2:$D$801,3,0),"") -> COLL | F11: =IFERROR(VLOOKUP(A11,sortir!$B$2:$C$60,2,0),"") -> 164 | G11: =IFERROR(VLOOKUP(A11,var!B:C,2,0),"") -> Daulat sitorus
A12: 688868a7-408e-44ae-b238-348dfc1995b0 | B12: 616 | C12: =IFERROR(VLOOKUP(A12,var!$B$2:$D$801,3,0),"") -> COLL | F12: =IFERROR(VLOOKUP(A12,sortir!$B$2:$C$60,2,0),"") -> 616 | G12: =IFERROR(VLOOKUP(A12,var!B:C,2,0),"") -> Juliendra
A13: 6b2e8be3-4c18-47cd-bfc4-5a119bd3b15d | B13: 10 | C13: =IFERROR(VLOOKUP(A13,var!$B$2:$D$801,3,0),"") -> ALL | F13: =IFERROR(VLOOKUP(A13,sortir!$B$2:$C$60,2,0),"") | G13: =IFERROR(VLOOKUP(A13,var!B:C,2,0),"") -> Galih sangga persada
A14: 6b3dc071-be8e-4fa6-84b3-ef2c87247cf2 | B14: 3 | C14: =IFERROR(VLOOKUP(A14,var!$B$2:$D$801,3,0),"") -> COLL | F14: =IFERROR(VLOOKUP(A14,sortir!$B$2:$C$60,2,0),"") -> 3 | G14: =IFERROR(VLOOKUP(A14,var!B:C,2,0),"") -> Opendi banjarnahor
A15: 6d21de4b-42fc-49f2-86f3-40a2a9759695 | B15: 215 | C15: =IFERROR(VLOOKUP(A15,var!$B$2:$D$801,3,0),"") -> COLL | F15: =IFERROR(VLOOKUP(A15,sortir!$B$2:$C$60,2,0),"") -> 215 | G15: =IFERROR(VLOOKUP(A15,var!B:C,2,0),"") -> Roby radiansyah
A16: 702dc462-24c0-4894-b1c2-8bb9fe7a2806 | B16: 255 | C16: =IFERROR(VLOOKUP(A16,var!$B$2:$D$801,3,0),"") -> COLL | F16: =IFERROR(VLOOKUP(A16,sortir!$B$2:$C$60,2,0),"") -> 255 | G16: =IFERROR(VLOOKUP(A16,var!B:C,2,0),"") -> Pantom Togi gabriel
A17: 74bb1709-aa7b-4b41-a082-a2af867fd15e | B17: 518 | C17: =IFERROR(VLOOKUP(A17,var!$B$2:$D$801,3,0),"") -> COLL | F17: =IFERROR(VLOOKUP(A17,sortir!$B$2:$C$60,2,0),"") -> 518 | G17: =IFERROR(VLOOKUP(A17,var!B:C,2,0),"") -> Bryan Saptarika
A18: 78c8aa58-d259-49a1-a96c-192417985ecf | B18: 130 | C18: =IFERROR(VLOOKUP(A18,var!$B$2:$D$801,3,0),"") -> COLL | F18: =IFERROR(VLOOKUP(A18,sortir!$B$2:$C$60,2,0),"") -> 130 | G18: =IFERROR(VLOOKUP(A18,var!B:C,2,0),"") -> ALDO FALERIO TAMBUNAN
A19: 83ca24fc-042d-4a7a-aea3-35465e9db033 | B19: 41 | C19: =IFERROR(VLOOKUP(A19,var!$B$2:$D$801,3,0),"") -> COLL | F19: =IFERROR(VLOOKUP(A19,sortir!$B$2:$C$60,2,0),"") -> 41 | G19: =IFERROR(VLOOKUP(A19,var!B:C,2,0),"") -> JUBRAIDER SIANTURI
... A32: fced54d3-7c26-48e8-91fe-7d7236e7f959 | B32: 3 | C32: =IFERROR(VLOOKUP(A32,var!$B$2:$D$801,3,0),"") -> COLL | F32: =IFERROR(VLOOKUP(A32,sortir!$B$2:$C$60,2,0),"") -> 3 | G32: =IFERROR(VLOOKUP(A32,var!B:C,2,0),"") -> Tiopan Lumbantoruan
C33: =IFERROR(VLOOKUP(A33,var!$B$2:$D$801,3,0),"") | F33: =IFERROR(VLOOKUP(A33,sortir!$B$2:$C$60,2,0),"") | G33: =IFERROR(VLOOKUP(A33,var!B:C,2,0),"")
C34: =IFERROR(VLOOKUP(A34,var!$B$2:$D$801,3,0),"") | F34: =IFERROR(VLOOKUP(A34,sortir!$B$2:$C$60,2,0),"") | G34: =IFERROR(VLOOKUP(A34,var!B:C,2,0),"")
C35: =IFERROR(VLOOKUP(A35,var!$B$2:$D$801,3,0),"") | F35: =IFERROR(VLOOKUP(A35,sortir!$B$2:$C$60,2,0),"") | G35: =IFERROR(VLOOKUP(A35,var!B:C,2,0),"")
C36: =IFERROR(VLOOKUP(A36,var!$B$2:$D$801,3,0),"") | F36: =IFERROR(VLOOKUP(A36,sortir!$B$2:$C$60,2,0),"") | G36: =IFERROR(VLOOKUP(A36,var!B:C,2,0),"")
C37: =IFERROR(VLOOKUP(A37,var!$B$2:$D$801,3,0),"") | F37: =IFERROR(VLOOKUP(A37,sortir!$B$2:$C$60,2,0),"") | G37: =IFERROR(VLOOKUP(A37,var!B:C,2,0),"")
C38: =IFERROR(VLOOKUP(A38,var!$B$2:$D$801,3,0),"") | F38: =IFERROR(VLOOKUP(A38,sortir!$B$2:$C$60,2,0),"") | G38: =IFERROR(VLOOKUP(A38,var!B:C,2,0),"")
C39: =IFERROR(VLOOKUP(A39,var!$B$2:$D$801,3,0),"") | F39: =IFERROR(VLOOKUP(A39,sortir!$B$2:$C$60,2,0),"") | G39: =IFERROR(VLOOKUP(A39,var!B:C,2,0),"")
C40: =IFERROR(VLOOKUP(A40,var!$B$2:$D$801,3,0),"") | F40: =IFERROR(VLOOKUP(A40,sortir!$B$2:$C$60,2,0),"") | G40: =IFERROR(VLOOKUP(A40,var!B:C,2,0),"")
C41: =IFERROR(VLOOKUP(A41,var!$B$2:$D$801,3,0),"") | F41: =IFERROR(VLOOKUP(A41,sortir!$B$2:$C$60,2,0),"") | G41: =IFERROR(VLOOKUP(A41,var!B:C,2,0),"")
C42: =IFERROR(VLOOKUP(A42,var!$B$2:$D$801,3,0),"") | F42: =IFERROR(VLOOKUP(A42,sortir!$B$2:$C$60,2,0),"") | G42: =IFERROR(VLOOKUP(A42,var!B:C,2,0),"")
C43: =IFERROR(VLOOKUP(A43,var!$B$2:$D$801,3,0),"") | F43: =IFERROR(VLOOKUP(A43,sortir!$B$2:$C$60,2,0),"") | G43: =IFERROR(VLOOKUP(A43,var!B:C,2,0),"")
C44: =IFERROR(VLOOKUP(A44,var!$B$2:$D$801,3,0),"") | F44: =IFERROR(VLOOKUP(A44,sortir!$B$2:$C$60,2,0),"") | G44: =IFERROR(VLOOKUP(A44,var!B:C,2,0),"")
... C70: =IFERROR(VLOOKUP(A70,var!$B$2:$D$801,3,0),"") | F70: =IFERROR(VLOOKUP(A70,sortir!$B$2:$C$60,2,0),"") | G70: =IFERROR(VLOOKUP(A70,var!B:C,2,0),"")

Sheet deteconfg
A1: user_id | B1: lokasi | C1: nopol_on_csv | D1: no_perjanjian | E1: nama_nasabah | F1: nopol | G1: coll | H1: pic | I1: kategori | J1: jto | K1: no_rangka | L1: no_mesin | M1: merk | N1: type | O1: warna | P1: status | Q1: actual_penyelesaian | R1: angsuran_ke | S1: tenor | T1: pic_foto | U1: team | V1: keterangan | W1: penyelesain | X1: case_id
A2: 97b899c7-a738-4c0c-a57d-47d1be720bd2 | D2: SP-24-F0001325 | E2: {=VLOOKUP($D2,[1]core!$D$2:$S$6032,COLUMN(B:B),0)} -> MARIANI | F2: {=VLOOKUP($D2,[1]core!$D$2:$S$6032,COLUMN(C:C),0)} -> BP 2604 FU | G2: {=VLOOKUP($D2,[1]core!$D$2:$S$6032,COLUMN(D:D),0)} -> C0 | H2: {=VLOOKUP($D2,[1]core!$D$2:$S$6032,COLUMN(E:E),0)} -> 03.DAULAT | I2: {=VLOOKUP($D2,[1]core!$D$2:$S$6032,COLUMN(F:F),0)} -> A | J2: {=VLOOKUP($D2,[1]core!$D$2:$S$6032,COLUMN(G:G),0)} -> 2 | K2: {=VLOOKUP($D2,[1]core!$D$2:$S$6032,COLUMN(H:H),0)} -> MH1JM4111KK557279 | L2: {=VLOOKUP($D2,[1]core!$D$2:$S$6032,COLUMN(I:I),0)} -> JM41E1557165 | M2: {=VLOOKUP($D2,[1]core!$D$2:$S$6032,COLUMN(J:J),0)} -> HONDA | N2: {=VLOOKUP($D2,[1]core!$D$2:$S$6032,COLUMN(K:K),0)} -> VARIO | O2: {=VLOOKUP($D2,[1]core!$D$2:$S$6032,COLUMN(L:L),0)} -> MERAH | P2: {=VLOOKUP($D2,[1]core!$D$2:$S$6032,COLUMN(M:M),0)} -> JG | Q2: {=VLOOKUP($D2,[1]core!$D$2:$S$6032,COLUMN(N:N),0)} -> DONE | R2: {=VLOOKUP($D2,[1]core!$D$2:$S$6032,COLUMN(O:O),0)} -> 16 | S2: {=VLOOKUP($D2,[1]core!$D$2:$S$6032,COLUMN(P:P),0)} -> 18 | T2: =VLOOKUP(A2,var!B:C,2,0) -> dokalorenpurba | U2: =VLOOKUP(A2,var!B:D,3,0) -> COLL
A3: 688868a7-408e-44ae-b238-348dfc1995b0 | D3: OD-24-F0002899 | E3: {=VLOOKUP($D3,[1]core!$D$2:$S$6032,COLUMN(B:B),0)} -> ANDI SETIAWAN | F3: {=VLOOKUP($D3,[1]core!$D$2:$S$6032,COLUMN(C:C),0)} -> BP 6941 UO | G3: {=VLOOKUP($D3,[1]core!$D$2:$S$6032,COLUMN(D:D),0)} -> C0 | H3: {=VLOOKUP($D3,[1]core!$D$2:$S$6032,COLUMN(E:E),0)} -> 10.MIDUK | I3: {=VLOOKUP($D3,[1]core!$D$2:$S$6032,COLUMN(F:F),0)} -> A | J3: {=VLOOKUP($D3,[1]core!$D$2:$S$6032,COLUMN(G:G),0)} -> 15 | K3: {=VLOOKUP($D3,[1]core!$D$2:$S$6032,COLUMN(H:H),0)} -> MH1JM8137RK109003 | L3: {=VLOOKUP($D3,[1]core!$D$2:$S$6032,COLUMN(I:I),0)} -> JM81E3107883 | M3: {=VLOOKUP($D3,[1]core!$D$2:$S$6032,COLUMN(J:J),0)} -> HONDA | N3: {=VLOOKUP($D3,[1]core!$D$2:$S$6032,COLUMN(K:K),0)} -> BEAT | O3: {=VLOOKUP($D3,[1]core!$D$2:$S$6032,COLUMN(L:L),0)} -> HITAM | P3: {=VLOOKUP($D3,[1]core!$D$2:$S$6032,COLUMN(M:M),0)} -> JG | Q3: {=VLOOKUP($D3,[1]core!$D$2:$S$6032,COLUMN(N:N),0)} -> BELUM JTO | R3: {=VLOOKUP($D3,[1]core!$D$2:$S$6032,COLUMN(O:O),0)} -> 13 | S3: {=VLOOKUP($D3,[1]core!$D$2:$S$6032,COLUMN(P:P),0)} -> 18 | T3: =VLOOKUP(A3,var!B:C,2,0) -> Juliendra | U3: =VLOOKUP(A3,var!B:D,3,0) -> COLL
A4: e3a70ada-a915-4680-aaa7-28e4b7d6722b | D4: OD-25-F0000508 | E4: {=VLOOKUP($D4,[1]core!$D$2:$S$6032,COLUMN(B:B),0)} -> MUTOHAROH | F4: {=VLOOKUP($D4,[1]core!$D$2:$S$6032,COLUMN(C:C),0)} -> BP 2802 RP | G4: {=VLOOKUP($D4,[1]core!$D$2:$S$6032,COLUMN(D:D),0)} -> C0 | H4: {=VLOOKUP($D4,[1]core!$D$2:$S$6032,COLUMN(E:E),0)} -> 07.RINTO | I4: {=VLOOKUP($D4,[1]core!$D$2:$S$6032,COLUMN(F:F),0)} -> A | J4: {=VLOOKUP($D4,[1]core!$D$2:$S$6032,COLUMN(G:G),0)} -> 1 | K4: {=VLOOKUP($D4,[1]core!$D$2:$S$6032,COLUMN(H:H),0)} -> MH1JM0415PK418798 | L4: {=VLOOKUP($D4,[1]core!$D$2:$S$6032,COLUMN(I:I),0)} -> JM04E1418638 | M4: {=VLOOKUP($D4,[1]core!$D$2:$S$6032,COLUMN(J:J),0)} -> HONDA | N4: {=VLOOKUP($D4,[1]core!$D$2:$S$6032,COLUMN(K:K),0)} -> SCOOPY | O4: {=VLOOKUP($D4,[1]core!$D$2:$S$6032,COLUMN(L:L),0)} -> HIJAU | P4: {=VLOOKUP($D4,[1]core!$D$2:$S$6032,COLUMN(M:M),0)} -> JG | Q4: {=VLOOKUP($D4,[1]core!$D$2:$S$6032,COLUMN(N:N),0)} -> GAGAL BAYAR | R4: {=VLOOKUP($D4,[1]core!$D$2:$S$6032,COLUMN(O:O),0)} -> 8 | S4: {=VLOOKUP($D4,[1]core!$D$2:$S$6032,COLUMN(P:P),0)} -> 18 | T4: =VLOOKUP(A4,var!B:C,2,0) -> Romroben sihombing | U4: =VLOOKUP(A4,var!B:D,3,0) -> COLL
A5: e3a70ada-a915-4680-aaa7-28e4b7d6722b | D5: OD-25-F0001935 | E5: {=VLOOKUP($D5,[1]core!$D$2:$S$6032,COLUMN(B:B),0)} -> JOSRI SIJABAT | F5: {=VLOOKUP($D5,[1]core!$D$2:$S$6032,COLUMN(C:C),0)} -> BP 3503 OD | G5: {=VLOOKUP($D5,[1]core!$D$2:$S$6032,COLUMN(D:D),0)} -> BELUM JTO | H5: {=VLOOKUP($D5,[1]core!$D$2:$S$6032,COLUMN(E:E),0)} -> C | I5: {=VLOOKUP($D5,[1]core!$D$2:$S$6032,COLUMN(F:F),0)} | J5: {=VLOOKUP($D5,[1]core!$D$2:$S$6032,COLUMN(G:G),0)} -> 1 | K5: {=VLOOKUP($D5,[1]core!$D$2:$S$6032,COLUMN(H:H),0)} -> MH1JM911XMK901000 | L5: {=VLOOKUP($D5,[1]core!$D$2:$S$6032,COLUMN(I:I),0)} -> JM91E1900395 | M5: {=VLOOKUP($D5,[1]core!$D$2:$S$6032,COLUMN(J:J),0)} -> HONDA | N5: {=VLOOKUP($D5,[1]core!$D$2:$S$6032,COLUMN(K:K),0)} -> BEAT | O5: {=VLOOKUP($D5,[1]core!$D$2:$S$6032,COLUMN(L:L),0)} -> HITAM | P5: {=VLOOKUP($D5,[1]core!$D$2:$S$6032,COLUMN(M:M),0)} -> JG | Q5: {=VLOOKUP($D5,[1]core!$D$2:$S$6032,COLUMN(N:N),0)} -> BELUM JTO | R5: {=VLOOKUP($D5,[1]core!$D$2:$S$6032,COLUMN(O:O),0)} -> 1 | S5: {=VLOOKUP($D5,[1]core!$D$2:$S$6032,COLUMN(P:P),0)} -> 18 | T5: =VLOOKUP(A5,var!B:C,2,0) -> Romroben sihombing | U5: =VLOOKUP(A5,var!B:D,3,0) -> COLL
A6: e3a70ada-a915-4680-aaa7-28e4b7d6722b | D6: SP-25-F0001868 | E6: {=VLOOKUP($D6,[1]core!$D$2:$S$6032,COLUMN(B:B),0)} -> RINO ARI MUKTI | F6: {=VLOOKUP($D6,[1]core!$D$2:$S$6032,COLUMN(C:C),0)} -> BP 3218 RH | G6: {=VLOOKUP($D6,[1]core!$D$2:$S$6032,COLUMN(D:D),0)} -> BELUM JTO | H6: {=VLOOKUP($D6,[1]core!$D$2:$S$6032,COLUMN(E:E),0)} -> C | I6: {=VLOOKUP($D6,[1]core!$D$2:$S$6032,COLUMN(F:F),0)} | J6: {=VLOOKUP($D6,[1]core!$D$2:$S$6032,COLUMN(G:G),0)} -> 1 | K6: {=VLOOKUP($D6,[1]core!$D$2:$S$6032,COLUMN(H:H),0)} -> MH1JM021XNK642472 | L6: {=VLOOKUP($D6,[1]core!$D$2:$S$6032,COLUMN(I:I),0)} -> JM02E1640421 | M6: {=VLOOKUP($D6,[1]core!$D$2:$S$6032,COLUMN(J:J),0)} -> HONDA | N6: {=VLOOKUP($D6,[1]core!$D$2:$S$6032,COLUMN(K:K),0)} -> SCOOPY KEYLEES | O6: {=VLOOKUP($D6,[1]core!$D$2:$S$6032,COLUMN(L:L),0)} -> PUTIH | P6: {=VLOOKUP($D6,[1]core!$D$2:$S$6032,COLUMN(M:M),0)} -> JG | Q6: {=VLOOKUP($D6,[1]core!$D$2:$S$6032,COLUMN(N:N),0)} -> BELUM JTO | R6: {=VLOOKUP($D6,[1]core!$D$2:$S$6032,COLUMN(O:O),0)} -> 4 | S6: {=VLOOKUP($D6,[1]core!$D$2:$S$6032,COLUMN(P:P),0)} -> 12 | T6: =VLOOKUP(A6,var!B:C,2,0) -> Romroben sihombing | U6: =VLOOKUP(A6,var!B:D,3,0) -> COLL
A7: e3a70ada-a915-4680-aaa7-28e4b7d6722b | D7: SP-24-F0002276 | E7: {=VLOOKUP($D7,[1]core!$D$2:$S$6032,COLUMN(B:B),0)} -> ANDERIAS YERU | F7: {=VLOOKUP($D7,[1]core!$D$2:$S$6032,COLUMN(C:C),0)} -> BP 3077 OD | G7: {=VLOOKUP($D7,[1]core!$D$2:$S$6032,COLUMN(D:D),0)} -> New C1 | H7: {=VLOOKUP($D7,[1]core!$D$2:$S$6032,COLUMN(E:E),0)} -> EVENDI | I7: {=VLOOKUP($D7,[1]core!$D$2:$S$6032,COLUMN(F:F),0)} | J7: {=VLOOKUP($D7,[1]core!$D$2:$S$6032,COLUMN(G:G),0)} -> 26 | K7: {=VLOOKUP($D7,[1]core!$D$2:$S$6032,COLUMN(H:H),0)} -> MH1JM8118MK784575 | L7: {=VLOOKUP($D7,[1]core!$D$2:$S$6032,COLUMN(I:I),0)} -> JM81E1786599 | M7: {=VLOOKUP($D7,[1]core!$D$2:$S$6032,COLUMN(J:J),0)} -> HONDA | N7: {=VLOOKUP($D7,[1]core!$D$2:$S$6032,COLUMN(K:K),0)} -> BEAT | O7: {=VLOOKUP($D7,[1]core!$D$2:$S$6032,COLUMN(L:L),0)} -> PUTIH HITAM | P7: {=VLOOKUP($D7,[1]core!$D$2:$S$6032,COLUMN(M:M),0)} -> JG | Q7: {=VLOOKUP($D7,[1]core!$D$2:$S$6032,COLUMN(N:N),0)} -> GAGAL BAYAR | R7: {=VLOOKUP($D7,[1]core!$D$2:$S$6032,COLUMN(O:O),0)} -> 12 | S7: {=VLOOKUP($D7,[1]core!$D$2:$S$6032,COLUMN(P:P),0)} -> 18 | T7: =VLOOKUP(A7,var!B:C,2,0) -> Romroben sihombing | U7: =VLOOKUP(A7,var!B:D,3,0) -> COLL
A8: 2d9d422f-1d0e-4451-8950-dc9e388e3850 | D8: OD-25-F0000998 | E8: {=VLOOKUP($D8,[1]core!$D$2:$S$6032,COLUMN(B:B),0)} -> IMAM SAFI I | F8: {=VLOOKUP($D8,[1]core!$D$2:$S$6032,COLUMN(C:C),0)} -> BP 2789 HI | G8: {=VLOOKUP($D8,[1]core!$D$2:$S$6032,COLUMN(D:D),0)} -> BELUM JTO | H8: {=VLOOKUP($D8,[1]core!$D$2:$S$6032,COLUMN(E:E),0)} -> C | I8: {=VLOOKUP($D8,[1]core!$D$2:$S$6032,COLUMN(F:F),0)} | J8: {=VLOOKUP($D8,[1]core!$D$2:$S$6032,COLUMN(G:G),0)} -> 1 | K8: {=VLOOKUP($D8,[1]core!$D$2:$S$6032,COLUMN(H:H),0)} -> MH1KF4110JK025437 | L8: {=VLOOKUP($D8,[1]core!$D$2:$S$6032,COLUMN(I:I),0)} -> KF41E1026285 | M8: {=VLOOKUP($D8,[1]core!$D$2:$S$6032,COLUMN(J:J),0)} -> HONDA | N8: {=VLOOKUP($D8,[1]core!$D$2:$S$6032,COLUMN(K:K),0)} -> VARIO | O8: {=VLOOKUP($D8,[1]core!$D$2:$S$6032,COLUMN(L:L),0)} -> HITAM | P8: {=VLOOKUP($D8,[1]core!$D$2:$S$6032,COLUMN(M:M),0)} -> JG | Q8: {=VLOOKUP($D8,[1]core!$D$2:$S$6032,COLUMN(N:N),0)} -> BELUM JTO | R8: {=VLOOKUP($D8,[1]core!$D$2:$S$6032,COLUMN(O:O),0)} -> 7 | S8: {=VLOOKUP($D8,[1]core!$D$2:$S$6032,COLUMN(P:P),0)} -> 18 | T8: =VLOOKUP(A8,var!B:C,2,0) -> Efendi Lim | U8: =VLOOKUP(A8,var!B:D,3,0) -> COLL
A9: 6d21de4b-42fc-49f2-86f3-40a2a9759695 | D9: OD-24-F0001038 | E9: {=VLOOKUP($D9,[1]core!$D$2:$S$6032,COLUMN(B:B),0)} -> AGUSMAN ZEGA | F9: {=VLOOKUP($D9,[1]core!$D$2:$S$6032,COLUMN(C:C),0)} -> BP 2167 US | G9: {=VLOOKUP($D9,[1]core!$D$2:$S$6032,COLUMN(D:D),0)} -> C0 | H9: {=VLOOKUP($D9,[1]core!$D$2:$S$6032,COLUMN(E:E),0)} -> 14.CALL CENTER | I9: {=VLOOKUP($D9,[1]core!$D$2:$S$6032,COLUMN(F:F),0)} -> A | J9: {=VLOOKUP($D9,[1]core!$D$2:$S$6032,COLUMN(G:G),0)} -> 15 | K9: {=VLOOKUP($D9,[1]core!$D$2:$S$6032,COLUMN(H:H),0)} -> MH1JM8128PK721828 | L9: {=VLOOKUP($D9,[1]core!$D$2:$S$6032,COLUMN(I:I),0)} -> JM81E2723848 | M9: {=VLOOKUP($D9,[1]core!$D$2:$S$6032,COLUMN(J:J),0)} -> HONDA | N9: {=VLOOKUP($D9,[1]core!$D$2:$S$6032,COLUMN(K:K),0)} -> BEAT | O9: {=VLOOKUP($D9,[1]core!$D$2:$S$6032,COLUMN(L:L),0)} -> BIRU HITAM | P9: {=VLOOKUP($D9,[1]core!$D$2:$S$6032,COLUMN(M:M),0)} -> JG | Q9: {=VLOOKUP($D9,[1]core!$D$2:$S$6032,COLUMN(N:N),0)} -> BELUM JTO | R9: {=VLOOKUP($D9,[1]core!$D$2:$S$6032,COLUMN(O:O),0)} -> 19 | S9: {=VLOOKUP($D9,[1]core!$D$2:$S$6032,COLUMN(P:P),0)} -> 24 | T9: =VLOOKUP(A9,var!B:C,2,0) -> Roby radiansyah | U9: =VLOOKUP(A9,var!B:D,3,0) -> COLL
A10: 86c5db36-c6d1-4806-9a2e-31a2483c0bb3 | D10: OD-25-F0000998 | E10: {=VLOOKUP($D10,[1]core!$D$2:$S$6032,COLUMN(B:B),0)} -> IMAM SAFI I | F10: {=VLOOKUP($D10,[1]core!$D$2:$S$6032,COLUMN(C:C),0)} -> BP 2789 HI | G10: {=VLOOKUP($D10,[1]core!$D$2:$S$6032,COLUMN(D:D),0)} -> BELUM JTO | H10: {=VLOOKUP($D10,[1]core!$D$2:$S$6032,COLUMN(E:E),0)} -> C | I10: {=VLOOKUP($D10,[1]core!$D$2:$S$6032,COLUMN(F:F),0)} | J10: {=VLOOKUP($D10,[1]core!$D$2:$S$6032,COLUMN(G:G),0)} -> 1 | K10: {=VLOOKUP($D10,[1]core!$D$2:$S$6032,COLUMN(H:H),0)} -> MH1KF4110JK025437 | L10: {=VLOOKUP($D10,[1]core!$D$2:$S$6032,COLUMN(I:I),0)} -> KF41E1026285 | M10: {=VLOOKUP($D10,[1]core!$D$2:$S$6032,COLUMN(J:J),0)} -> HONDA | N10: {=VLOOKUP($D10,[1]core!$D$2:$S$6032,COLUMN(K:K),0)} -> VARIO | O10: {=VLOOKUP($D10,[1]core!$D$2:$S$6032,COLUMN(L:L),0)} -> HITAM | P10: {=VLOOKUP($D10,[1]core!$D$2:$S$6032,COLUMN(M:M),0)} -> JG | Q10: {=VLOOKUP($D10,[1]core!$D$2:$S$6032,COLUMN(N:N),0)} -> BELUM JTO | R10: {=VLOOKUP($D10,[1]core!$D$2:$S$6032,COLUMN(O:O),0)} -> 7 | S10: {=VLOOKUP($D10,[1]core!$D$2:$S$6032,COLUMN(P:P),0)} -> 18 | T10: =VLOOKUP(A10,var!B:C,2,0) -> BOSPA SIANIPAR | U10: =VLOOKUP(A10,var!B:D,3,0) -> COLL
A11: 78c8aa58-d259-49a1-a96c-192417985ecf | D11: OD-25-F0000998 | E11: {=VLOOKUP($D11,[1]core!$D$2:$S$6032,COLUMN(B:B),0)} -> IMAM SAFI I | F11: {=VLOOKUP($D11,[1]core!$D$2:$S$6032,COLUMN(C:C),0)} -> BP 2789 HI | G11: {=VLOOKUP($D11,[1]core!$D$2:$S$6032,COLUMN(D:D),0)} -> BELUM JTO | H11: {=VLOOKUP($D11,[1]core!$D$2:$S$6032,COLUMN(E:E),0)} -> C | I11: {=VLOOKUP($D11,[1]core!$D$2:$S$6032,COLUMN(F:F),0)} | J11: {=VLOOKUP($D11,[1]core!$D$2:$S$6032,COLUMN(G:G),0)} -> 1 | K11: {=VLOOKUP($D11,[1]core!$D$2:$S$6032,COLUMN(H:H),0)} -> MH1KF4110JK025437 | L11: {=VLOOKUP($D11,[1]core!$D$2:$S$6032,COLUMN(I:I),0)} -> KF41E1026285 | M11: {=VLOOKUP($D11,[1]core!$D$2:$S$6032,COLUMN(J:J),0)} -> HONDA | N11: {=VLOOKUP($D11,[1]core!$D$2:$S$6032,COLUMN(K:K),0)} -> VARIO | O11: {=VLOOKUP($D11,[1]core!$D$2:$S$6032,COLUMN(L:L),0)} -> HITAM | P11: {=VLOOKUP($D11,[1]core!$D$2:$S$6032,COLUMN(M:M),0)} -> JG | Q11: {=VLOOKUP($D11,[1]core!$D$2:$S$6032,COLUMN(N:N),0)} -> BELUM JTO | R11: {=VLOOKUP($D11,[1]core!$D$2:$S$6032,COLUMN(O:O),0)} -> 7 | S11: {=VLOOKUP($D11,[1]core!$D$2:$S$6032,COLUMN(P:P),0)} -> 18 | T11: =VLOOKUP(A11,var!B:C,2,0) -> ALDO FALERIO TAMBUNAN | U11: =VLOOKUP(A11,var!B:D,3,0) -> COLL
A12: 78c8aa58-d259-49a1-a96c-192417985ecf | D12: OD-25-F0001935 | E12: {=VLOOKUP($D12,[1]core!$D$2:$S$6032,COLUMN(B:B),0)} -> JOSRI SIJABAT | F12: {=VLOOKUP($D12,[1]core!$D$2:$S$6032,COLUMN(C:C),0)} -> BP 3503 OD | G12: {=VLOOKUP($D12,[1]core!$D$2:$S$6032,COLUMN(D:D),0)} -> BELUM JTO | H12: {=VLOOKUP($D12,[1]core!$D$2:$S$6032,COLUMN(E:E),0)} -> C | I12: {=VLOOKUP($D12,[1]core!$D$2:$S$6032,COLUMN(F:F),0)} | J12: {=VLOOKUP($D12,[1]core!$D$2:$S$6032,COLUMN(G:G),0)} -> 1 | K12: {=VLOOKUP($D12,[1]core!$D$2:$S$6032,COLUMN(H:H),0)} -> MH1JM911XMK901000 | L12: {=VLOOKUP($D12,[1]core!$D$2:$S$6032,COLUMN(I:I),0)} -> JM91E1900395 | M12: {=VLOOKUP($D12,[1]core!$D$2:$S$6032,COLUMN(J:J),0)} -> HONDA | N12: {=VLOOKUP($D12,[1]core!$D$2:$S$6032,COLUMN(K:K),0)} -> BEAT | O12: {=VLOOKUP($D12,[1]core!$D$2:$S$6032,COLUMN(L:L),0)} -> HITAM | P12: {=VLOOKUP($D12,[1]core!$D$2:$S$6032,COLUMN(M:M),0)} -> JG | Q12: {=VLOOKUP($D12,[1]core!$D$2:$S$6032,COLUMN(N:N),0)} -> BELUM JTO | R12: {=VLOOKUP($D12,[1]core!$D$2:$S$6032,COLUMN(O:O),0)} -> 1 | S12: {=VLOOKUP($D12,[1]core!$D$2:$S$6032,COLUMN(P:P),0)} -> 18 | T12: =VLOOKUP(A12,var!B:C,2,0) -> ALDO FALERIO TAMBUNAN | U12: =VLOOKUP(A12,var!B:D,3,0) -> COLL
A13: 78c8aa58-d259-49a1-a96c-192417985ecf | D13: SP-24-F0002276 | E13: {=VLOOKUP($D13,[1]core!$D$2:$S$6032,COLUMN(B:B),0)} -> ANDERIAS YERU | F13: {=VLOOKUP($D13,[1]core!$D$2:$S$6032,COLUMN(C:C),0)} -> BP 3077 OD | G13: {=VLOOKUP($D13,[1]core!$D$2:$S$6032,COLUMN(D:D),0)} -> New C1 | H13: {=VLOOKUP($D13,[1]core!$D$2:$S$6032,COLUMN(E:E),0)} -> EVENDI | I13: {=VLOOKUP($D13,[1]core!$D$2:$S$6032,COLUMN(F:F),0)} | J13: {=VLOOKUP($D13,[1]core!$D$2:$S$6032,COLUMN(G:G),0)} -> 26 | K13: {=VLOOKUP($D13,[1]core!$D$2:$S$6032,COLUMN(H:H),0)} -> MH1JM8118MK784575 | L13: {=VLOOKUP($D13,[1]core!$D$2:$S$6032,COLUMN(I:I),0)} -> JM81E1786599 | M13: {=VLOOKUP($D13,[1]core!$D$2:$S$6032,COLUMN(J:J),0)} -> HONDA | N13: {=VLOOKUP($D13,[1]core!$D$2:$S$6032,COLUMN(K:K),0)} -> BEAT | O13: {=VLOOKUP($D13,[1]core!$D$2:$S$6032,COLUMN(L:L),0)} -> PUTIH HITAM | P13: {=VLOOKUP($D13,[1]core!$D$2:$S$6032,COLUMN(M:M),0)} -> JG | Q13: {=VLOOKUP($D13,[1]core!$D$2:$S$6032,COLUMN(N:N),0)} -> GAGAL BAYAR | R13: {=VLOOKUP($D13,[1]core!$D$2:$S$6032,COLUMN(O:O),0)} -> 12 | S13: {=VLOOKUP($D13,[1]core!$D$2:$S$6032,COLUMN(P:P),0)} -> 18 | T13: =VLOOKUP(A13,var!B:C,2,0) -> ALDO FALERIO TAMBUNAN | U13: =VLOOKUP(A13,var!B:D,3,0) -> COLL
... A47: 03ad1f6b-7a85-463b-ab53-e8f3deee2ad5 | D47: BT-KD-23-00182 | E47: {=VLOOKUP($D47,[1]core!$D$2:$S$6032,COLUMN(B:B),0)} -> #N/A | F47: {=VLOOKUP($D47,[1]core!$D$2:$S$6032,COLUMN(C:C),0)} -> #N/A | G47: {=VLOOKUP($D47,[1]core!$D$2:$S$6032,COLUMN(D:D),0)} -> #N/A | H47: {=VLOOKUP($D47,[1]core!$D$2:$S$6032,COLUMN(E:E),0)} -> #N/A | I47: {=VLOOKUP($D47,[1]core!$D$2:$S$6032,COLUMN(F:F),0)} -> #N/A | J47: {=VLOOKUP($D47,[1]core!$D$2:$S$6032,COLUMN(G:G),0)} -> #N/A | K47: {=VLOOKUP($D47,[1]core!$D$2:$S$6032,COLUMN(H:H),0)} -> #N/A | L47: {=VLOOKUP($D47,[1]core!$D$2:$S$6032,COLUMN(I:I),0)} -> #N/A | M47: {=VLOOKUP($D47,[1]core!$D$2:$S$6032,COLUMN(J:J),0)} -> #N/A | N47: {=VLOOKUP($D47,[1]core!$D$2:$S$6032,COLUMN(K:K),0)} -> #N/A | O47: {=VLOOKUP($D47,[1]core!$D$2:$S$6032,COLUMN(L:L),0)} -> #N/A | P47: {=VLOOKUP($D47,[1]core!$D$2:$S$6032,COLUMN(M:M),0)} -> #N/A | Q47: {=VLOOKUP($D47,[1]core!$D$2:$S$6032,COLUMN(N:N),0)} -> #N/A | R47: {=VLOOKUP($D47,[1]core!$D$2:$S$6032,COLUMN(O:O),0)} -> #N/A | S47: {=VLOOKUP($D47,[1]core!$D$2:$S$6032,COLUMN(P:P),0)} -> #N/A | T47: =VLOOKUP(A47,var!B:C,2,0) -> Ray Steven Hutabarat | U47: =VLOOKUP(A47,var!B:D,3,0) -> COLL
A48: 6d21de4b-42fc-49f2-86f3-40a2a9759695 | D48: 13003167 | E48: {=VLOOKUP($D48,[1]core!$D$2:$S$6032,COLUMN(B:B),0)} -> #N/A | F48: {=VLOOKUP($D48,[1]core!$D$2:$S$6032,COLUMN(C:C),0)} -> #N/A | G48: {=VLOOKUP($D48,[1]core!$D$2:$S$6032,COLUMN(D:D),0)} -> #N/A | H48: {=VLOOKUP($D48,[1]core!$D$2:$S$6032,COLUMN(E:E),0)} -> #N/A | I48: {=VLOOKUP($D48,[1]core!$D$2:$S$6032,COLUMN(F:F),0)} -> #N/A | J48: {=VLOOKUP($D48,[1]core!$D$2:$S$6032,COLUMN(G:G),0)} -> #N/A | K48: {=VLOOKUP($D48,[1]core!$D$2:$S$6032,COLUMN(H:H),0)} -> #N/A | L48: {=VLOOKUP($D48,[1]core!$D$2:$S$6032,COLUMN(I:I),0)} -> #N/A | M48: {=VLOOKUP($D48,[1]core!$D$2:$S$6032,COLUMN(J:J),0)} -> #N/A | N48: {=VLOOKUP($D48,[1]core!$D$2:$S$6032,COLUMN(K:K),0)} -> #N/A | O48: {=VLOOKUP($D48,[1]core!$D$2:$S$6032,COLUMN(L:L),0)} -> #N/A | P48: {=VLOOKUP($D48,[1]core!$D$2:$S$6032,COLUMN(M:M),0)} -> #N/A | Q48: {=VLOOKUP($D48,[1]core!$D$2:$S$6032,COLUMN(N:N),0)} -> #N/A | R48: {=VLOOKUP($D48,[1]core!$D$2:$S$6032,COLUMN(O:O),0)} -> #N/A | S48: {=VLOOKUP($D48,[1]core!$D$2:$S$6032,COLUMN(P:P),0)} -> #N/A | T48: =VLOOKUP(A48,var!B:C,2,0) -> Roby radiansyah | U48: =VLOOKUP(A48,var!B:D,3,0) -> COLL
A49: e0d931cf-6e64-4a91-a81a-04cf02d33a39 | D49: OD-24-F0001836 | E49: {=VLOOKUP($D49,[1]core!$D$2:$S$6032,COLUMN(B:B),0)} -> ROSI NOVIZA | F49: {=VLOOKUP($D49,[1]core!$D$2:$S$6032,COLUMN(C:C),0)} -> BP 3998 IG | G49: {=VLOOKUP($D49,[1]core!$D$2:$S$6032,COLUMN(D:D),0)} -> C0 | H49: {=VLOOKUP($D49,[1]core!$D$2:$S$6032,COLUMN(E:E),0)} -> 14.CALL CENTER | I49: {=VLOOKUP($D49,[1]core!$D$2:$S$6032,COLUMN(F:F),0)} -> A | J49: {=VLOOKUP($D49,[1]core!$D$2:$S$6032,COLUMN(G:G),0)} -> 6 | K49: {=VLOOKUP($D49,[1]core!$D$2:$S$6032,COLUMN(H:H),0)} -> MH1JFC118DK191067 | L49: {=VLOOKUP($D49,[1]core!$D$2:$S$6032,COLUMN(I:I),0)} -> JFC1E1190679 | M49: {=VLOOKUP($D49,[1]core!$D$2:$S$6032,COLUMN(J:J),0)} -> HONDA | N49: {=VLOOKUP($D49,[1]core!$D$2:$S$6032,COLUMN(K:K),0)} -> VARIO | O49: {=VLOOKUP($D49,[1]core!$D$2:$S$6032,COLUMN(L:L),0)} -> HITAM | P49: {=VLOOKUP($D49,[1]core!$D$2:$S$6032,COLUMN(M:M),0)} -> JG | Q49: {=VLOOKUP($D49,[1]core!$D$2:$S$6032,COLUMN(N:N),0)} -> DONE | R49: {=VLOOKUP($D49,[1]core!$D$2:$S$6032,COLUMN(O:O),0)} -> 16 | S49: {=VLOOKUP($D49,[1]core!$D$2:$S$6032,COLUMN(P:P),0)} -> 24 | T49: =VLOOKUP(A49,var!B:C,2,0) -> Agus setiyawan | U49: =VLOOKUP(A49,var!B:D,3,0) -> COLL
A50: 6d21de4b-42fc-49f2-86f3-40a2a9759695 | D50: TP-25-F0000511 | E50: {=VLOOKUP($D50,[1]core!$D$2:$S$6032,COLUMN(B:B),0)} -> TOYANI | F50: {=VLOOKUP($D50,[1]core!$D$2:$S$6032,COLUMN(C:C),0)} -> BP 3676 JB | G50: {=VLOOKUP($D50,[1]core!$D$2:$S$6032,COLUMN(D:D),0)} -> C0 | H50: {=VLOOKUP($D50,[1]core!$D$2:$S$6032,COLUMN(E:E),0)} -> 01.SYAMSURI | I50: {=VLOOKUP($D50,[1]core!$D$2:$S$6032,COLUMN(F:F),0)} -> A | J50: {=VLOOKUP($D50,[1]core!$D$2:$S$6032,COLUMN(G:G),0)} -> 15 | K50: {=VLOOKUP($D50,[1]core!$D$2:$S$6032,COLUMN(H:H),0)} -> MH1JM3135LK724658 | L50: {=VLOOKUP($D50,[1]core!$D$2:$S$6032,COLUMN(I:I),0)} -> JM31E3723591 | M50: {=VLOOKUP($D50,[1]core!$D$2:$S$6032,COLUMN(J:J),0)} -> HONDA | N50: {=VLOOKUP($D50,[1]core!$D$2:$S$6032,COLUMN(K:K),0)} -> SCOOPY | O50: {=VLOOKUP($D50,[1]core!$D$2:$S$6032,COLUMN(L:L),0)} -> HITAM | P50: {=VLOOKUP($D50,[1]core!$D$2:$S$6032,COLUMN(M:M),0)} -> JG | Q50: {=VLOOKUP($D50,[1]core!$D$2:$S$6032,COLUMN(N:N),0)} -> BELUM JTO | R50: {=VLOOKUP($D50,[1]core!$D$2:$S$6032,COLUMN(O:O),0)} -> 4 | S50: {=VLOOKUP($D50,[1]core!$D$2:$S$6032,COLUMN(P:P),0)} -> 24 | T50: =VLOOKUP(A50,var!B:C,2,0) -> Roby radiansyah | U50: =VLOOKUP(A50,var!B:D,3,0) -> COLL
E51: {=VLOOKUP($D51,[1]core!$D$2:$S$6032,COLUMN(B:B),0)} -> #N/A | F51: {=VLOOKUP($D51,[1]core!$D$2:$S$6032,COLUMN(C:C),0)} -> #N/A | G51: {=VLOOKUP($D51,[1]core!$D$2:$S$6032,COLUMN(D:D),0)} -> #N/A | H51: {=VLOOKUP($D51,[1]core!$D$2:$S$6032,COLUMN(E:E),0)} -> #N/A | I51: {=VLOOKUP($D51,[1]core!$D$2:$S$6032,COLUMN(F:F),0)} -> #N/A | J51: {=VLOOKUP($D51,[1]core!$D$2:$S$6032,COLUMN(G:G),0)} -> #N/A | K51: {=VLOOKUP($D51,[1]core!$D$2:$S$6032,COLUMN(H:H),0)} -> #N/A | L51: {=VLOOKUP($D51,[1]core!$D$2:$S$6032,COLUMN(I:I),0)} -> #N/A | M51: {=VLOOKUP($D51,[1]core!$D$2:$S$6032,COLUMN(J:J),0)} -> #N/A | N51: {=VLOOKUP($D51,[1]core!$D$2:$S$6032,COLUMN(K:K),0)} -> #N/A | O51: {=VLOOKUP($D51,[1]core!$D$2:$S$6032,COLUMN(L:L),0)} -> #N/A | P51: {=VLOOKUP($D51,[1]core!$D$2:$S$6032,COLUMN(M:M),0)} -> #N/A | Q51: {=VLOOKUP($D51,[1]core!$D$2:$S$6032,COLUMN(N:N),0)} -> #N/A | R51: {=VLOOKUP($D51,[1]core!$D$2:$S$6032,COLUMN(O:O),0)} -> #N/A | S51: {=VLOOKUP($D51,[1]core!$D$2:$S$6032,COLUMN(P:P),0)} -> #N/A | T51: =VLOOKUP(A51,var!B:C,2,0) -> #N/A | U51: =VLOOKUP(A51,var!B:D,3,0) -> #N/A
E52: {=VLOOKUP($D52,[1]core!$D$2:$S$6032,COLUMN(B:B),0)} -> #N/A | F52: {=VLOOKUP($D52,[1]core!$D$2:$S$6032,COLUMN(C:C),0)} -> #N/A | G52: {=VLOOKUP($D52,[1]core!$D$2:$S$6032,COLUMN(D:D),0)} -> #N/A | H52: {=VLOOKUP($D52,[1]core!$D$2:$S$6032,COLUMN(E:E),0)} -> #N/A | I52: {=VLOOKUP($D52,[1]core!$D$2:$S$6032,COLUMN(F:F),0)} -> #N/A | J52: {=VLOOKUP($D52,[1]core!$D$2:$S$6032,COLUMN(G:G),0)} -> #N/A | K52: {=VLOOKUP($D52,[1]core!$D$2:$S$6032,COLUMN(H:H),0)} -> #N/A | L52: {=VLOOKUP($D52,[1]core!$D$2:$S$6032,COLUMN(I:I),0)} -> #N/A | M52: {=VLOOKUP($D52,[1]core!$D$2:$S$6032,COLUMN(J:J),0)} -> #N/A | N52: {=VLOOKUP($D52,[1]core!$D$2:$S$6032,COLUMN(K:K),0)} -> #N/A | O52: {=VLOOKUP($D52,[1]core!$D$2:$S$6032,COLUMN(L:L),0)} -> #N/A | P52: {=VLOOKUP($D52,[1]core!$D$2:$S$6032,COLUMN(M:M),0)} -> #N/A | Q52: {=VLOOKUP($D52,[1]core!$D$2:$S$6032,COLUMN(N:N),0)} -> #N/A | R52: {=VLOOKUP($D52,[1]core!$D$2:$S$6032,COLUMN(O:O),0)} -> #N/A | S52: {=VLOOKUP($D52,[1]core!$D$2:$S$6032,COLUMN(P:P),0)} -> #N/A | T52: =VLOOKUP(A52,var!B:C,2,0) -> #N/A | U52: =VLOOKUP(A52,var!B:D,3,0) -> #N/A
E53: {=VLOOKUP($D53,[1]core!$D$2:$S$6032,COLUMN(B:B),0)} -> #N/A | F53: {=VLOOKUP($D53,[1]core!$D$2:$S$6032,COLUMN(C:C),0)} -> #N/A | G53: {=VLOOKUP($D53,[1]core!$D$2:$S$6032,COLUMN(D:D),0)} -> #N/A | H53: {=VLOOKUP($D53,[1]core!$D$2:$S$6032,COLUMN(E:E),0)} -> #N/A | I53: {=VLOOKUP($D53,[1]core!$D$2:$S$6032,COLUMN(F:F),0)} -> #N/A | J53: {=VLOOKUP($D53,[1]core!$D$2:$S$6032,COLUMN(G:G),0)} -> #N/A | K53: {=VLOOKUP($D53,[1]core!$D$2:$S$6032,COLUMN(H:H),0)} -> #N/A | L53: {=VLOOKUP($D53,[1]core!$D$2:$S$6032,COLUMN(I:I),0)} -> #N/A | M53: {=VLOOKUP($D53,[1]core!$D$2:$S$6032,COLUMN(J:J),0)} -> #N/A | N53: {=VLOOKUP($D53,[1]core!$D$2:$S$6032,COLUMN(K:K),0)} -> #N/A | O53: {=VLOOKUP($D53,[1]core!$D$2:$S$6032,COLUMN(L:L),0)} -> #N/A | P53: {=VLOOKUP($D53,[1]core!$D$2:$S$6032,COLUMN(M:M),0)} -> #N/A | Q53: {=VLOOKUP($D53,[1]core!$D$2:$S$6032,COLUMN(N:N),0)} -> #N/A | R53: {=VLOOKUP($D53,[1]core!$D$2:$S$6032,COLUMN(O:O),0)} -> #N/A | S53: {=VLOOKUP($D53,[1]core!$D$2:$S$6032,COLUMN(P:P),0)} -> #N/A | T53: =VLOOKUP(A53,var!B:C,2,0) -> #N/A | U53: =VLOOKUP(A53,var!B:D,3,0) -> #N/A
E54: {=VLOOKUP($D54,[1]core!$D$2:$S$6032,COLUMN(B:B),0)} -> #N/A | F54: {=VLOOKUP($D54,[1]core!$D$2:$S$6032,COLUMN(C:C),0)} -> #N/A | G54: {=VLOOKUP($D54,[1]core!$D$2:$S$6032,COLUMN(D:D),0)} -> #N/A | H54: {=VLOOKUP($D54,[1]core!$D$2:$S$6032,COLUMN(E:E),0)} -> #N/A | I54: {=VLOOKUP($D54,[1]core!$D$2:$S$6032,COLUMN(F:F),0)} -> #N/A | J54: {=VLOOKUP($D54,[1]core!$D$2:$S$6032,COLUMN(G:G),0)} -> #N/A | K54: {=VLOOKUP($D54,[1]core!$D$2:$S$6032,COLUMN(H:H),0)} -> #N/A | L54: {=VLOOKUP($D54,[1]core!$D$2:$S$6032,COLUMN(I:I),0)} -> #N/A | M54: {=VLOOKUP($D54,[1]core!$D$2:$S$6032,COLUMN(J:J),0)} -> #N/A | N54: {=VLOOKUP($D54,[1]core!$D$2:$S$6032,COLUMN(K:K),0)} -> #N/A | O54: {=VLOOKUP($D54,[1]core!$D$2:$S$6032,COLUMN(L:L),0)} -> #N/A | P54: {=VLOOKUP($D54,[1]core!$D$2:$S$6032,COLUMN(M:M),0)} -> #N/A | Q54: {=VLOOKUP($D54,[1]core!$D$2:$S$6032,COLUMN(N:N),0)} -> #N/A | R54: {=VLOOKUP($D54,[1]core!$D$2:$S$6032,COLUMN(O:O),0)} -> #N/A | S54: {=VLOOKUP($D54,[1]core!$D$2:$S$6032,COLUMN(P:P),0)} -> #N/A | T54: =VLOOKUP(A54,var!B:C,2,0) -> #N/A | U54: =VLOOKUP(A54,var!B:D,3,0) -> #N/A
E55: {=VLOOKUP($D55,[1]core!$D$2:$S$6032,COLUMN(B:B),0)} -> #N/A | F55: {=VLOOKUP($D55,[1]core!$D$2:$S$6032,COLUMN(C:C),0)} -> #N/A | G55: {=VLOOKUP($D55,[1]core!$D$2:$S$6032,COLUMN(D:D),0)} -> #N/A | H55: {=VLOOKUP($D55,[1]core!$D$2:$S$6032,COLUMN(E:E),0)} -> #N/A | I55: {=VLOOKUP($D55,[1]core!$D$2:$S$6032,COLUMN(F:F),0)} -> #N/A | J55: {=VLOOKUP($D55,[1]core!$D$2:$S$6032,COLUMN(G:G),0)} -> #N/A | K55: {=VLOOKUP($D55,[1]core!$D$2:$S$6032,COLUMN(H:H),0)} -> #N/A | L55: {=VLOOKUP($D55,[1]core!$D$2:$S$6032,COLUMN(I:I),0)} -> #N/A | M55: {=VLOOKUP($D55,[1]core!$D$2:$S$6032,COLUMN(J:J),0)} -> #N/A | N55: {=VLOOKUP($D55,[1]core!$D$2:$S$6032,COLUMN(K:K),0)} -> #N/A | O55: {=VLOOKUP($D55,[1]core!$D$2:$S$6032,COLUMN(L:L),0)} -> #N/A | P55: {=VLOOKUP($D55,[1]core!$D$2:$S$6032,COLUMN(M:M),0)} -> #N/A | Q55: {=VLOOKUP($D55,[1]core!$D$2:$S$6032,COLUMN(N:N),0)} -> #N/A | R55: {=VLOOKUP($D55,[1]core!$D$2:$S$6032,COLUMN(O:O),0)} -> #N/A | S55: {=VLOOKUP($D55,[1]core!$D$2:$S$6032,COLUMN(P:P),0)} -> #N/A | T55: =VLOOKUP(A55,var!B:C,2,0) -> #N/A | U55: =VLOOKUP(A55,var!B:D,3,0) -> #N/A
E56: {=VLOOKUP($D56,[1]core!$D$2:$S$6032,COLUMN(B:B),0)} -> #N/A | F56: {=VLOOKUP($D56,[1]core!$D$2:$S$6032,COLUMN(C:C),0)} -> #N/A | G56: {=VLOOKUP($D56,[1]core!$D$2:$S$6032,COLUMN(D:D),0)} -> #N/A | H56: {=VLOOKUP($D56,[1]core!$D$2:$S$6032,COLUMN(E:E),0)} -> #N/A | I56: {=VLOOKUP($D56,[1]core!$D$2:$S$6032,COLUMN(F:F),0)} -> #N/A | J56: {=VLOOKUP($D56,[1]core!$D$2:$S$6032,COLUMN(G:G),0)} -> #N/A | K56: {=VLOOKUP($D56,[1]core!$D$2:$S$6032,COLUMN(H:H),0)} -> #N/A | L56: {=VLOOKUP($D56,[1]core!$D$2:$S$6032,COLUMN(I:I),0)} -> #N/A | M56: {=VLOOKUP($D56,[1]core!$D$2:$S$6032,COLUMN(J:J),0)} -> #N/A | N56: {=VLOOKUP($D56,[1]core!$D$2:$S$6032,COLUMN(K:K),0)} -> #N/A | O56: {=VLOOKUP($D56,[1]core!$D$2:$S$6032,COLUMN(L:L),0)} -> #N/A | P56: {=VLOOKUP($D56,[1]core!$D$2:$S$6032,COLUMN(M:M),0)} -> #N/A | Q56: {=VLOOKUP($D56,[1]core!$D$2:$S$6032,COLUMN(N:N),0)} -> #N/A | R56: {=VLOOKUP($D56,[1]core!$D$2:$S$6032,COLUMN(O:O),0)} -> #N/A | S56: {=VLOOKUP($D56,[1]core!$D$2:$S$6032,COLUMN(P:P),0)} -> #N/A | T56: =VLOOKUP(A56,var!B:C,2,0) -> #N/A | U56: =VLOOKUP(A56,var!B:D,3,0) -> #N/A
E57: {=VLOOKUP($D57,[1]core!$D$2:$S$6032,COLUMN(B:B),0)} -> #N/A | F57: {=VLOOKUP($D57,[1]core!$D$2:$S$6032,COLUMN(C:C),0)} -> #N/A | G57: {=VLOOKUP($D57,[1]core!$D$2:$S$6032,COLUMN(D:D),0)} -> #N/A | H57: {=VLOOKUP($D57,[1]core!$D$2:$S$6032,COLUMN(E:E),0)} -> #N/A | I57: {=VLOOKUP($D57,[1]core!$D$2:$S$6032,COLUMN(F:F),0)} -> #N/A | J57: {=VLOOKUP($D57,[1]core!$D$2:$S$6032,COLUMN(G:G),0)} -> #N/A | K57: {=VLOOKUP($D57,[1]core!$D$2:$S$6032,COLUMN(H:H),0)} -> #N/A | L57: {=VLOOKUP($D57,[1]core!$D$2:$S$6032,COLUMN(I:I),0)} -> #N/A | M57: {=VLOOKUP($D57,[1]core!$D$2:$S$6032,COLUMN(J:J),0)} -> #N/A | N57: {=VLOOKUP($D57,[1]core!$D$2:$S$6032,COLUMN(K:K),0)} -> #N/A | O57: {=VLOOKUP($D57,[1]core!$D$2:$S$6032,COLUMN(L:L),0)} -> #N/A | P57: {=VLOOKUP($D57,[1]core!$D$2:$S$6032,COLUMN(M:M),0)} -> #N/A | Q57: {=VLOOKUP($D57,[1]core!$D$2:$S$6032,COLUMN(N:N),0)} -> #N/A | R57: {=VLOOKUP($D57,[1]core!$D$2:$S$6032,COLUMN(O:O),0)} -> #N/A | S57: {=VLOOKUP($D57,[1]core!$D$2:$S$6032,COLUMN(P:P),0)} -> #N/A | T57: =VLOOKUP(A57,var!B:C,2,0) -> #N/A | U57: =VLOOKUP(A57,var!B:D,3,0) -> #N/A
E58: {=VLOOKUP($D58,[1]core!$D$2:$S$6032,COLUMN(B:B),0)} -> #N/A | F58: {=VLOOKUP($D58,[1]core!$D$2:$S$6032,COLUMN(C:C),0)} -> #N/A | G58: {=VLOOKUP($D58,[1]core!$D$2:$S$6032,COLUMN(D:D),0)} -> #N/A | H58: {=VLOOKUP($D58,[1]core!$D$2:$S$6032,COLUMN(E:E),0)} -> #N/A | I58: {=VLOOKUP($D58,[1]core!$D$2:$S$6032,COLUMN(F:F),0)} -> #N/A | J58: {=VLOOKUP($D58,[1]core!$D$2:$S$6032,COLUMN(G:G),0)} -> #N/A | K58: {=VLOOKUP($D58,[1]core!$D$2:$S$6032,COLUMN(H:H),0)} -> #N/A | L58: {=VLOOKUP($D58,[1]core!$D$2:$S$6032,COLUMN(I:I),0)} -> #N/A | M58: {=VLOOKUP($D58,[1]core!$D$2:$S$6032,COLUMN(J:J),0)} -> #N/A | N58: {=VLOOKUP($D58,[1]core!$D$2:$S$6032,COLUMN(K:K),0)} -> #N/A | O58: {=VLOOKUP($D58,[1]core!$D$2:$S$6032,COLUMN(L:L),0)} -> #N/A | P58: {=VLOOKUP($D58,[1]core!$D$2:$S$6032,COLUMN(M:M),0)} -> #N/A | Q58: {=VLOOKUP($D58,[1]core!$D$2:$S$6032,COLUMN(N:N),0)} -> #N/A | R58: {=VLOOKUP($D58,[1]core!$D$2:$S$6032,COLUMN(O:O),0)} -> #N/A | S58: {=VLOOKUP($D58,[1]core!$D$2:$S$6032,COLUMN(P:P),0)} -> #N/A | T58: =VLOOKUP(A58,var!B:C,2,0) -> #N/A | U58: =VLOOKUP(A58,var!B:D,3,0) -> #N/A
E59: {=VLOOKUP($D59,[1]core!$D$2:$S$6032,COLUMN(B:B),0)} -> #N/A | F59: {=VLOOKUP($D59,[1]core!$D$2:$S$6032,COLUMN(C:C),0)} -> #N/A | G59: {=VLOOKUP($D59,[1]core!$D$2:$S$6032,COLUMN(D:D),0)} -> #N/A | H59: {=VLOOKUP($D59,[1]core!$D$2:$S$6032,COLUMN(E:E),0)} -> #N/A | I59: {=VLOOKUP($D59,[1]core!$D$2:$S$6032,COLUMN(F:F),0)} -> #N/A | J59: {=VLOOKUP($D59,[1]core!$D$2:$S$6032,COLUMN(G:G),0)} -> #N/A | K59: {=VLOOKUP($D59,[1]core!$D$2:$S$6032,COLUMN(H:H),0)} -> #N/A | L59: {=VLOOKUP($D59,[1]core!$D$2:$S$6032,COLUMN(I:I),0)} -> #N/A | M59: {=VLOOKUP($D59,[1]core!$D$2:$S$6032,COLUMN(J:J),0)} -> #N/A | N59: {=VLOOKUP($D59,[1]core!$D$2:$S$6032,COLUMN(K:K),0)} -> #N/A | O59: {=VLOOKUP($D59,[1]core!$D$2:$S$6032,COLUMN(L:L),0)} -> #N/A | P59: {=VLOOKUP($D59,[1]core!$D$2:$S$6032,COLUMN(M:M),0)} -> #N/A | Q59: {=VLOOKUP($D59,[1]core!$D$2:$S$6032,COLUMN(N:N),0)} -> #N/A | R59: {=VLOOKUP($D59,[1]core!$D$2:$S$6032,COLUMN(O:O),0)} -> #N/A | S59: {=VLOOKUP($D59,[1]core!$D$2:$S$6032,COLUMN(P:P),0)} -> #N/A | T59: =VLOOKUP(A59,var!B:C,2,0) -> #N/A | U59: =VLOOKUP(A59,var!B:D,3,0) -> #N/A
E60: {=VLOOKUP($D60,[1]core!$D$2:$S$6032,COLUMN(B:B),0)} -> #N/A | F60: {=VLOOKUP($D60,[1]core!$D$2:$S$6032,COLUMN(C:C),0)} -> #N/A | G60: {=VLOOKUP($D60,[1]core!$D$2:$S$6032,COLUMN(D:D),0)} -> #N/A | H60: {=VLOOKUP($D60,[1]core!$D$2:$S$6032,COLUMN(E:E),0)} -> #N/A | I60: {=VLOOKUP($D60,[1]core!$D$2:$S$6032,COLUMN(F:F),0)} -> #N/A | J60: {=VLOOKUP($D60,[1]core!$D$2:$S$6032,COLUMN(G:G),0)} -> #N/A | K60: {=VLOOKUP($D60,[1]core!$D$2:$S$6032,COLUMN(H:H),0)} -> #N/A | L60: {=VLOOKUP($D60,[1]core!$D$2:$S$6032,COLUMN(I:I),0)} -> #N/A | M60: {=VLOOKUP($D60,[1]core!$D$2:$S$6032,COLUMN(J:J),0)} -> #N/A | N60: {=VLOOKUP($D60,[1]core!$D$2:$S$6032,COLUMN(K:K),0)} -> #N/A | O60: {=VLOOKUP($D60,[1]core!$D$2:$S$6032,COLUMN(L:L),0)} -> #N/A | P60: {=VLOOKUP($D60,[1]core!$D$2:$S$6032,COLUMN(M:M),0)} -> #N/A | Q60: {=VLOOKUP($D60,[1]core!$D$2:$S$6032,COLUMN(N:N),0)} -> #N/A | R60: {=VLOOKUP($D60,[1]core!$D$2:$S$6032,COLUMN(O:O),0)} -> #N/A | S60: {=VLOOKUP($D60,[1]core!$D$2:$S$6032,COLUMN(P:P),0)} -> #N/A | T60: =VLOOKUP(A60,var!B:C,2,0) -> #N/A | U60: =VLOOKUP(A60,var!B:D,3,0) -> #N/A
E61: {=VLOOKUP($D61,[1]core!$D$2:$S$6032,COLUMN(B:B),0)} -> #N/A | F61: {=VLOOKUP($D61,[1]core!$D$2:$S$6032,COLUMN(C:C),0)} -> #N/A | G61: {=VLOOKUP($D61,[1]core!$D$2:$S$6032,COLUMN(D:D),0)} -> #N/A | H61: {=VLOOKUP($D61,[1]core!$D$2:$S$6032,COLUMN(E:E),0)} -> #N/A | I61: {=VLOOKUP($D61,[1]core!$D$2:$S$6032,COLUMN(F:F),0)} -> #N/A | J61: {=VLOOKUP($D61,[1]core!$D$2:$S$6032,COLUMN(G:G),0)} -> #N/A | K61: {=VLOOKUP($D61,[1]core!$D$2:$S$6032,COLUMN(H:H),0)} -> #N/A | L61: {=VLOOKUP($D61,[1]core!$D$2:$S$6032,COLUMN(I:I),0)} -> #N/A | M61: {=VLOOKUP($D61,[1]core!$D$2:$S$6032,COLUMN(J:J),0)} -> #N/A | N61: {=VLOOKUP($D61,[1]core!$D$2:$S$6032,COLUMN(K:K),0)} -> #N/A | O61: {=VLOOKUP($D61,[1]core!$D$2:$S$6032,COLUMN(L:L),0)} -> #N/A | P61: {=VLOOKUP($D61,[1]core!$D$2:$S$6032,COLUMN(M:M),0)} -> #N/A | Q61: {=VLOOKUP($D61,[1]core!$D$2:$S$6032,COLUMN(N:N),0)} -> #N/A | R61: {=VLOOKUP($D61,[1]core!$D$2:$S$6032,COLUMN(O:O),0)} -> #N/A | S61: {=VLOOKUP($D61,[1]core!$D$2:$S$6032,COLUMN(P:P),0)} -> #N/A | T61: =VLOOKUP(A61,var!B:C,2,0) -> #N/A | U61: =VLOOKUP(A61,var!B:D,3,0) -> #N/A
E62: {=VLOOKUP($D62,[1]core!$D$2:$S$6032,COLUMN(B:B),0)} -> #N/A | F62: {=VLOOKUP($D62,[1]core!$D$2:$S$6032,COLUMN(C:C),0)} -> #N/A | G62: {=VLOOKUP($D62,[1]core!$D$2:$S$6032,COLUMN(D:D),0)} -> #N/A | H62: {=VLOOKUP($D62,[1]core!$D$2:$S$6032,COLUMN(E:E),0)} -> #N/A | I62: {=VLOOKUP($D62,[1]core!$D$2:$S$6032,COLUMN(F:F),0)} -> #N/A | J62: {=VLOOKUP($D62,[1]core!$D$2:$S$6032,COLUMN(G:G),0)} -> #N/A | K62: {=VLOOKUP($D62,[1]core!$D$2:$S$6032,COLUMN(H:H),0)} -> #N/A | L62: {=VLOOKUP($D62,[1]core!$D$2:$S$6032,COLUMN(I:I),0)} -> #N/A | M62: {=VLOOKUP($D62,[1]core!$D$2:$S$6032,COLUMN(J:J),0)} -> #N/A | N62: {=VLOOKUP($D62,[1]core!$D$2:$S$6032,COLUMN(K:K),0)} -> #N/A | O62: {=VLOOKUP($D62,[1]core!$D$2:$S$6032,COLUMN(L:L),0)} -> #N/A | P62: {=VLOOKUP($D62,[1]core!$D$2:$S$6032,COLUMN(M:M),0)} -> #N/A | Q62: {=VLOOKUP($D62,[1]core!$D$2:$S$6032,COLUMN(N:N),0)} -> #N/A | R62: {=VLOOKUP($D62,[1]core!$D$2:$S$6032,COLUMN(O:O),0)} -> #N/A | S62: {=VLOOKUP($D62,[1]core!$D$2:$S$6032,COLUMN(P:P),0)} -> #N/A | T62: =VLOOKUP(A62,var!B:C,2,0) -> #N/A | U62: =VLOOKUP(A62,var!B:D,3,0) -> #N/A
... E88: {=VLOOKUP($D88,[1]core!$D$2:$S$6032,COLUMN(B:B),0)} -> #N/A | F88: {=VLOOKUP($D88,[1]core!$D$2:$S$6032,COLUMN(C:C),0)} -> #N/A | G88: {=VLOOKUP($D88,[1]core!$D$2:$S$6032,COLUMN(D:D),0)} -> #N/A | H88: {=VLOOKUP($D88,[1]core!$D$2:$S$6032,COLUMN(E:E),0)} -> #N/A | I88: {=VLOOKUP($D88,[1]core!$D$2:$S$6032,COLUMN(F:F),0)} -> #N/A | J88: {=VLOOKUP($D88,[1]core!$D$2:$S$6032,COLUMN(G:G),0)} -> #N/A | K88: {=VLOOKUP($D88,[1]core!$D$2:$S$6032,COLUMN(H:H),0)} -> #N/A | L88: {=VLOOKUP($D88,[1]core!$D$2:$S$6032,COLUMN(I:I),0)} -> #N/A | M88: {=VLOOKUP($D88,[1]core!$D$2:$S$6032,COLUMN(J:J),0)} -> #N/A | N88: {=VLOOKUP($D88,[1]core!$D$2:$S$6032,COLUMN(K:K),0)} -> #N/A | O88: {=VLOOKUP($D88,[1]core!$D$2:$S$6032,COLUMN(L:L),0)} -> #N/A | P88: {=VLOOKUP($D88,[1]core!$D$2:$S$6032,COLUMN(M:M),0)} -> #N/A | Q88: {=VLOOKUP($D88,[1]core!$D$2:$S$6032,COLUMN(N:N),0)} -> #N/A | R88: {=VLOOKUP($D88,[1]core!$D$2:$S$6032,COLUMN(O:O),0)} -> #N/A | S88: {=VLOOKUP($D88,[1]core!$D$2:$S$6032,COLUMN(P:P),0)} -> #N/A | T88: =VLOOKUP(A88,var!B:C,2,0) -> #N/A | U88: =VLOOKUP(A88,var!B:D,3,0) -> #N/A
T89: =VLOOKUP(A89,var!B:C,2,0) -> #N/A | U89: =VLOOKUP(A89,var!B:D,3,0) -> #N/A
T90: =VLOOKUP(A90,var!B:C,2,0) -> #N/A | U90: =VLOOKUP(A90,var!B:D,3,0) -> #N/A
T91: =VLOOKUP(A91,var!B:C,2,0) -> #N/A | U91: =VLOOKUP(A91,var!B:D,3,0) -> #N/A
T92: =VLOOKUP(A92,var!B:C,2,0) -> #N/A | U92: =VLOOKUP(A92,var!B:D,3,0) -> #N/A
T93: =VLOOKUP(A93,var!B:C,2,0) -> #N/A | U93: =VLOOKUP(A93,var!B:D,3,0) -> #N/A
T94: =VLOOKUP(A94,var!B:C,2,0) -> #N/A | U94: =VLOOKUP(A94,var!B:D,3,0) -> #N/A
T95: =VLOOKUP(A95,var!B:C,2,0) -> #N/A | U95: =VLOOKUP(A95,var!B:D,3,0) -> #N/A
T96: =VLOOKUP(A96,var!B:C,2,0) -> #N/A | U96: =VLOOKUP(A96,var!B:D,3,0) -> #N/A
T97: =VLOOKUP(A97,var!B:C,2,0) -> #N/A | U97: =VLOOKUP(A97,var!B:D,3,0) -> #N/A
T98: =VLOOKUP(A98,var!B:C,2,0) -> #N/A | U98: =VLOOKUP(A98,var!B:D,3,0) -> #N/A
...

Sheet detecdb
A1: no | B1: no_perjanjian | C1: nama_nasabah | D1: nopol | E1: coll | F1: pic | G1: kategori | H1: jto | I1: no_rangka | J1: no_mesin | K1: merk | L1: type | M1: warna | N1: status | O1: actual_penyelesaian | P1: angsuran_ke | Q1: tenor
A2: 1 | B2: BN-23-F0000032 | C2: DWI KURNIA DESVANINGSIH | D2: BP 6637 ID | E2: C | F2: BELUM JTO | G2: A | H2: 5 | I2: MJAS16MS2PJ200311 | J2: QJ164FMLA12266096 | K2: BENELLI | L2: MOTOBI 200 EFI | M2: HITAM | N2: JG | O2: DONE | P2: 22 | Q2: 24
A3: 2 | B3: BN-23-F0000004 | C3: DODI TRIK JAYA | D3: BP 6355 ID | E3: C | F3: BELUM JTO | G3: A | H3: 1 | I3: MJAS17MS3PJ200247 | J3: BM255FMMB13502891 | K3: BENELLI | L3: P. EAGLE 250 | M3: HITAM | N3: JG | O3: DONE | P3: 26 | Q3: 36
